Internal Server Error: /
Traceback (most recent call last):
  File "/app/apps/home/context_processors.py", line 11, in <module>
    with open(assets_json_fname, 'r') as f:
FileNotFoundError: [Errno 2] No such file or directory: '/static/assets.json'

During handling of the above exception, another exception occurred:

Traceback (most recent call last):
  File "/usr/local/lib/python3.5/site-packages/django/core/handlers/base.py", line 149, in get_response
    response = self.process_exception_by_middleware(e, request)
  File "/usr/local/lib/python3.5/site-packages/django/core/handlers/base.py", line 147, in get_response
    response = wrapped_callback(request, *callback_args, **callback_kwargs)
  File "/app/apps/home/views.py", line 4, in index
    return render(request, 'home/index.html')
  File "/usr/local/lib/python3.5/site-packages/django/shortcuts.py", line 67, in render
    template_name, context, request=request, using=using)
  File "/usr/local/lib/python3.5/site-packages/django/template/loader.py", line 97, in render_to_string
    return template.render(context, request)
  File "/usr/local/lib/python3.5/site-packages/django/template/backends/django.py", line 95, in render
    return self.template.render(context)
  File "/usr/local/lib/python3.5/site-packages/django/template/base.py", line 204, in render
    with context.bind_template(self):
  File "/usr/local/lib/python3.5/contextlib.py", line 59, in __enter__
    return next(self.gen)
  File "/usr/local/lib/python3.5/site-packages/django/template/context.py", line 256, in bind_template
    processors = (template.engine.template_context_processors +
  File "/usr/local/lib/python3.5/site-packages/django/utils/functional.py", line 33, in __get__
    res = instance.__dict__[self.name] = self.func(instance)
  File "/usr/local/lib/python3.5/site-packages/django/template/engine.py", line 105, in template_context_processors
    return tuple(import_string(path) for path in context_processors)
  File "/usr/local/lib/python3.5/site-packages/django/template/engine.py", line 105, in <genexpr>
    return tuple(import_string(path) for path in context_processors)
  File "/usr/local/lib/python3.5/site-packages/django/utils/module_loading.py", line 20, in import_string
    module = import_module(module_path)
  File "/usr/local/lib/python3.5/importlib/__init__.py", line 126, in import_module
    return _bootstrap._gcd_import(name[level:], package, level)
  File "<frozen importlib._bootstrap>", line 986, in _gcd_import
  File "<frozen importlib._bootstrap>", line 969, in _find_and_load
  File "<frozen importlib._bootstrap>", line 958, in _find_and_load_unlocked
  File "<frozen importlib._bootstrap>", line 673, in _load_unlocked
  File "<frozen importlib._bootstrap_external>", line 662, in exec_module
  File "<frozen importlib._bootstrap>", line 222, in _call_with_frames_removed
  File "/app/apps/home/context_processors.py", line 14, in <module>
    raise Exception('failed to read %s. was frontend built?' % assets_json_fname)
Exception: failed to read /static/assets.json. was frontend built?
Internal Server Error: /favicon.ico
Traceback (most recent call last):
  File "/app/apps/home/context_processors.py", line 11, in <module>
    with open(assets_json_fname, 'r') as f:
FileNotFoundError: [Errno 2] No such file or directory: '/static/assets.json'

During handling of the above exception, another exception occurred:

Traceback (most recent call last):
  File "/usr/local/lib/python3.5/site-packages/django/core/handlers/base.py", line 149, in get_response
    response = self.process_exception_by_middleware(e, request)
  File "/usr/local/lib/python3.5/site-packages/django/core/handlers/base.py", line 147, in get_response
    response = wrapped_callback(request, *callback_args, **callback_kwargs)
  File "/app/apps/home/views.py", line 4, in index
    return render(request, 'home/index.html')
  File "/usr/local/lib/python3.5/site-packages/django/shortcuts.py", line 67, in render
    template_name, context, request=request, using=using)
  File "/usr/local/lib/python3.5/site-packages/django/template/loader.py", line 97, in render_to_string
    return template.render(context, request)
  File "/usr/local/lib/python3.5/site-packages/django/template/backends/django.py", line 95, in render
    return self.template.render(context)
  File "/usr/local/lib/python3.5/site-packages/django/template/base.py", line 204, in render
    with context.bind_template(self):
  File "/usr/local/lib/python3.5/contextlib.py", line 59, in __enter__
    return next(self.gen)
  File "/usr/local/lib/python3.5/site-packages/django/template/context.py", line 256, in bind_template
    processors = (template.engine.template_context_processors +
  File "/usr/local/lib/python3.5/site-packages/django/utils/functional.py", line 33, in __get__
    res = instance.__dict__[self.name] = self.func(instance)
  File "/usr/local/lib/python3.5/site-packages/django/template/engine.py", line 105, in template_context_processors
    return tuple(import_string(path) for path in context_processors)
  File "/usr/local/lib/python3.5/site-packages/django/template/engine.py", line 105, in <genexpr>
    return tuple(import_string(path) for path in context_processors)
  File "/usr/local/lib/python3.5/site-packages/django/utils/module_loading.py", line 20, in import_string
    module = import_module(module_path)
  File "/usr/local/lib/python3.5/importlib/__init__.py", line 126, in import_module
    return _bootstrap._gcd_import(name[level:], package, level)
  File "<frozen importlib._bootstrap>", line 986, in _gcd_import
  File "<frozen importlib._bootstrap>", line 969, in _find_and_load
  File "<frozen importlib._bootstrap>", line 958, in _find_and_load_unlocked
  File "<frozen importlib._bootstrap>", line 673, in _load_unlocked
  File "<frozen importlib._bootstrap_external>", line 662, in exec_module
  File "<frozen importlib._bootstrap>", line 222, in _call_with_frames_removed
  File "/app/apps/home/context_processors.py", line 14, in <module>
    raise Exception('failed to read %s. was frontend built?' % assets_json_fname)
Exception: failed to read /static/assets.json. was frontend built?
Internal Server Error: /favicon.ico
Traceback (most recent call last):
  File "/app/apps/home/context_processors.py", line 11, in <module>
    with open(assets_json_fname, 'r') as f:
FileNotFoundError: [Errno 2] No such file or directory: '/static/assets.json'

During handling of the above exception, another exception occurred:

Traceback (most recent call last):
  File "/usr/local/lib/python3.5/site-packages/django/core/handlers/base.py", line 149, in get_response
    response = self.process_exception_by_middleware(e, request)
  File "/usr/local/lib/python3.5/site-packages/django/core/handlers/base.py", line 147, in get_response
    response = wrapped_callback(request, *callback_args, **callback_kwargs)
  File "/app/apps/home/views.py", line 4, in index
    return render(request, 'home/index.html')
  File "/usr/local/lib/python3.5/site-packages/django/shortcuts.py", line 67, in render
    template_name, context, request=request, using=using)
  File "/usr/local/lib/python3.5/site-packages/django/template/loader.py", line 97, in render_to_string
    return template.render(context, request)
  File "/usr/local/lib/python3.5/site-packages/django/template/backends/django.py", line 95, in render
    return self.template.render(context)
  File "/usr/local/lib/python3.5/site-packages/django/template/base.py", line 204, in render
    with context.bind_template(self):
  File "/usr/local/lib/python3.5/contextlib.py", line 59, in __enter__
    return next(self.gen)
  File "/usr/local/lib/python3.5/site-packages/django/template/context.py", line 256, in bind_template
    processors = (template.engine.template_context_processors +
  File "/usr/local/lib/python3.5/site-packages/django/utils/functional.py", line 33, in __get__
    res = instance.__dict__[self.name] = self.func(instance)
  File "/usr/local/lib/python3.5/site-packages/django/template/engine.py", line 105, in template_context_processors
    return tuple(import_string(path) for path in context_processors)
  File "/usr/local/lib/python3.5/site-packages/django/template/engine.py", line 105, in <genexpr>
    return tuple(import_string(path) for path in context_processors)
  File "/usr/local/lib/python3.5/site-packages/django/utils/module_loading.py", line 20, in import_string
    module = import_module(module_path)
  File "/usr/local/lib/python3.5/importlib/__init__.py", line 126, in import_module
    return _bootstrap._gcd_import(name[level:], package, level)
  File "<frozen importlib._bootstrap>", line 986, in _gcd_import
  File "<frozen importlib._bootstrap>", line 969, in _find_and_load
  File "<frozen importlib._bootstrap>", line 958, in _find_and_load_unlocked
  File "<frozen importlib._bootstrap>", line 673, in _load_unlocked
  File "<frozen importlib._bootstrap_external>", line 662, in exec_module
  File "<frozen importlib._bootstrap>", line 222, in _call_with_frames_removed
  File "/app/apps/home/context_processors.py", line 14, in <module>
    raise Exception('failed to read %s. was frontend built?' % assets_json_fname)
Exception: failed to read /static/assets.json. was frontend built?
Internal Server Error: /
Traceback (most recent call last):
  File "/app/apps/home/context_processors.py", line 11, in <module>
    with open(assets_json_fname, 'r') as f:
FileNotFoundError: [Errno 2] No such file or directory: '/static/assets.json'

During handling of the above exception, another exception occurred:

Traceback (most recent call last):
  File "/usr/local/lib/python3.5/site-packages/django/core/handlers/base.py", line 149, in get_response
    response = self.process_exception_by_middleware(e, request)
  File "/usr/local/lib/python3.5/site-packages/django/core/handlers/base.py", line 147, in get_response
    response = wrapped_callback(request, *callback_args, **callback_kwargs)
  File "/app/apps/home/views.py", line 4, in index
    return render(request, 'home/index.html')
  File "/usr/local/lib/python3.5/site-packages/django/shortcuts.py", line 67, in render
    template_name, context, request=request, using=using)
  File "/usr/local/lib/python3.5/site-packages/django/template/loader.py", line 97, in render_to_string
    return template.render(context, request)
  File "/usr/local/lib/python3.5/site-packages/django/template/backends/django.py", line 95, in render
    return self.template.render(context)
  File "/usr/local/lib/python3.5/site-packages/django/template/base.py", line 204, in render
    with context.bind_template(self):
  File "/usr/local/lib/python3.5/contextlib.py", line 59, in __enter__
    return next(self.gen)
  File "/usr/local/lib/python3.5/site-packages/django/template/context.py", line 256, in bind_template
    processors = (template.engine.template_context_processors +
  File "/usr/local/lib/python3.5/site-packages/django/utils/functional.py", line 33, in __get__
    res = instance.__dict__[self.name] = self.func(instance)
  File "/usr/local/lib/python3.5/site-packages/django/template/engine.py", line 105, in template_context_processors
    return tuple(import_string(path) for path in context_processors)
  File "/usr/local/lib/python3.5/site-packages/django/template/engine.py", line 105, in <genexpr>
    return tuple(import_string(path) for path in context_processors)
  File "/usr/local/lib/python3.5/site-packages/django/utils/module_loading.py", line 20, in import_string
    module = import_module(module_path)
  File "/usr/local/lib/python3.5/importlib/__init__.py", line 126, in import_module
    return _bootstrap._gcd_import(name[level:], package, level)
  File "<frozen importlib._bootstrap>", line 986, in _gcd_import
  File "<frozen importlib._bootstrap>", line 969, in _find_and_load
  File "<frozen importlib._bootstrap>", line 958, in _find_and_load_unlocked
  File "<frozen importlib._bootstrap>", line 673, in _load_unlocked
  File "<frozen importlib._bootstrap_external>", line 662, in exec_module
  File "<frozen importlib._bootstrap>", line 222, in _call_with_frames_removed
  File "/app/apps/home/context_processors.py", line 14, in <module>
    raise Exception('failed to read %s. was frontend built?' % assets_json_fname)
Exception: failed to read /static/assets.json. was frontend built?
Internal Server Error: /favicon.ico
Traceback (most recent call last):
  File "/app/apps/home/context_processors.py", line 11, in <module>
    with open(assets_json_fname, 'r') as f:
FileNotFoundError: [Errno 2] No such file or directory: '/static/assets.json'

During handling of the above exception, another exception occurred:

Traceback (most recent call last):
  File "/usr/local/lib/python3.5/site-packages/django/core/handlers/base.py", line 149, in get_response
    response = self.process_exception_by_middleware(e, request)
  File "/usr/local/lib/python3.5/site-packages/django/core/handlers/base.py", line 147, in get_response
    response = wrapped_callback(request, *callback_args, **callback_kwargs)
  File "/app/apps/home/views.py", line 4, in index
    return render(request, 'home/index.html')
  File "/usr/local/lib/python3.5/site-packages/django/shortcuts.py", line 67, in render
    template_name, context, request=request, using=using)
  File "/usr/local/lib/python3.5/site-packages/django/template/loader.py", line 97, in render_to_string
    return template.render(context, request)
  File "/usr/local/lib/python3.5/site-packages/django/template/backends/django.py", line 95, in render
    return self.template.render(context)
  File "/usr/local/lib/python3.5/site-packages/django/template/base.py", line 204, in render
    with context.bind_template(self):
  File "/usr/local/lib/python3.5/contextlib.py", line 59, in __enter__
    return next(self.gen)
  File "/usr/local/lib/python3.5/site-packages/django/template/context.py", line 256, in bind_template
    processors = (template.engine.template_context_processors +
  File "/usr/local/lib/python3.5/site-packages/django/utils/functional.py", line 33, in __get__
    res = instance.__dict__[self.name] = self.func(instance)
  File "/usr/local/lib/python3.5/site-packages/django/template/engine.py", line 105, in template_context_processors
    return tuple(import_string(path) for path in context_processors)
  File "/usr/local/lib/python3.5/site-packages/django/template/engine.py", line 105, in <genexpr>
    return tuple(import_string(path) for path in context_processors)
  File "/usr/local/lib/python3.5/site-packages/django/utils/module_loading.py", line 20, in import_string
    module = import_module(module_path)
  File "/usr/local/lib/python3.5/importlib/__init__.py", line 126, in import_module
    return _bootstrap._gcd_import(name[level:], package, level)
  File "<frozen importlib._bootstrap>", line 986, in _gcd_import
  File "<frozen importlib._bootstrap>", line 969, in _find_and_load
  File "<frozen importlib._bootstrap>", line 958, in _find_and_load_unlocked
  File "<frozen importlib._bootstrap>", line 673, in _load_unlocked
  File "<frozen importlib._bootstrap_external>", line 662, in exec_module
  File "<frozen importlib._bootstrap>", line 222, in _call_with_frames_removed
  File "/app/apps/home/context_processors.py", line 14, in <module>
    raise Exception('failed to read %s. was frontend built?' % assets_json_fname)
Exception: failed to read /static/assets.json. was frontend built?
Internal Server Error: /
Traceback (most recent call last):
  File "/app/apps/home/context_processors.py", line 11, in <module>
    with open(assets_json_fname, 'r') as f:
FileNotFoundError: [Errno 2] No such file or directory: '/static/assets.json'

During handling of the above exception, another exception occurred:

Traceback (most recent call last):
  File "/usr/local/lib/python3.5/site-packages/django/core/handlers/base.py", line 149, in get_response
    response = self.process_exception_by_middleware(e, request)
  File "/usr/local/lib/python3.5/site-packages/django/core/handlers/base.py", line 147, in get_response
    response = wrapped_callback(request, *callback_args, **callback_kwargs)
  File "/app/apps/home/views.py", line 4, in index
    return render(request, 'home/index.html')
  File "/usr/local/lib/python3.5/site-packages/django/shortcuts.py", line 67, in render
    template_name, context, request=request, using=using)
  File "/usr/local/lib/python3.5/site-packages/django/template/loader.py", line 97, in render_to_string
    return template.render(context, request)
  File "/usr/local/lib/python3.5/site-packages/django/template/backends/django.py", line 95, in render
    return self.template.render(context)
  File "/usr/local/lib/python3.5/site-packages/django/template/base.py", line 204, in render
    with context.bind_template(self):
  File "/usr/local/lib/python3.5/contextlib.py", line 59, in __enter__
    return next(self.gen)
  File "/usr/local/lib/python3.5/site-packages/django/template/context.py", line 256, in bind_template
    processors = (template.engine.template_context_processors +
  File "/usr/local/lib/python3.5/site-packages/django/utils/functional.py", line 33, in __get__
    res = instance.__dict__[self.name] = self.func(instance)
  File "/usr/local/lib/python3.5/site-packages/django/template/engine.py", line 105, in template_context_processors
    return tuple(import_string(path) for path in context_processors)
  File "/usr/local/lib/python3.5/site-packages/django/template/engine.py", line 105, in <genexpr>
    return tuple(import_string(path) for path in context_processors)
  File "/usr/local/lib/python3.5/site-packages/django/utils/module_loading.py", line 20, in import_string
    module = import_module(module_path)
  File "/usr/local/lib/python3.5/importlib/__init__.py", line 126, in import_module
    return _bootstrap._gcd_import(name[level:], package, level)
  File "<frozen importlib._bootstrap>", line 986, in _gcd_import
  File "<frozen importlib._bootstrap>", line 969, in _find_and_load
  File "<frozen importlib._bootstrap>", line 958, in _find_and_load_unlocked
  File "<frozen importlib._bootstrap>", line 673, in _load_unlocked
  File "<frozen importlib._bootstrap_external>", line 662, in exec_module
  File "<frozen importlib._bootstrap>", line 222, in _call_with_frames_removed
  File "/app/apps/home/context_processors.py", line 14, in <module>
    raise Exception('failed to read %s. was frontend built?' % assets_json_fname)
Exception: failed to read /static/assets.json. was frontend built?
Internal Server Error: /favicon.ico
Traceback (most recent call last):
  File "/app/apps/home/context_processors.py", line 11, in <module>
    with open(assets_json_fname, 'r') as f:
FileNotFoundError: [Errno 2] No such file or directory: '/static/assets.json'

During handling of the above exception, another exception occurred:

Traceback (most recent call last):
  File "/usr/local/lib/python3.5/site-packages/django/core/handlers/base.py", line 149, in get_response
    response = self.process_exception_by_middleware(e, request)
  File "/usr/local/lib/python3.5/site-packages/django/core/handlers/base.py", line 147, in get_response
    response = wrapped_callback(request, *callback_args, **callback_kwargs)
  File "/app/apps/home/views.py", line 4, in index
    return render(request, 'home/index.html')
  File "/usr/local/lib/python3.5/site-packages/django/shortcuts.py", line 67, in render
    template_name, context, request=request, using=using)
  File "/usr/local/lib/python3.5/site-packages/django/template/loader.py", line 97, in render_to_string
    return template.render(context, request)
  File "/usr/local/lib/python3.5/site-packages/django/template/backends/django.py", line 95, in render
    return self.template.render(context)
  File "/usr/local/lib/python3.5/site-packages/django/template/base.py", line 204, in render
    with context.bind_template(self):
  File "/usr/local/lib/python3.5/contextlib.py", line 59, in __enter__
    return next(self.gen)
  File "/usr/local/lib/python3.5/site-packages/django/template/context.py", line 256, in bind_template
    processors = (template.engine.template_context_processors +
  File "/usr/local/lib/python3.5/site-packages/django/utils/functional.py", line 33, in __get__
    res = instance.__dict__[self.name] = self.func(instance)
  File "/usr/local/lib/python3.5/site-packages/django/template/engine.py", line 105, in template_context_processors
    return tuple(import_string(path) for path in context_processors)
  File "/usr/local/lib/python3.5/site-packages/django/template/engine.py", line 105, in <genexpr>
    return tuple(import_string(path) for path in context_processors)
  File "/usr/local/lib/python3.5/site-packages/django/utils/module_loading.py", line 20, in import_string
    module = import_module(module_path)
  File "/usr/local/lib/python3.5/importlib/__init__.py", line 126, in import_module
    return _bootstrap._gcd_import(name[level:], package, level)
  File "<frozen importlib._bootstrap>", line 986, in _gcd_import
  File "<frozen importlib._bootstrap>", line 969, in _find_and_load
  File "<frozen importlib._bootstrap>", line 958, in _find_and_load_unlocked
  File "<frozen importlib._bootstrap>", line 673, in _load_unlocked
  File "<frozen importlib._bootstrap_external>", line 662, in exec_module
  File "<frozen importlib._bootstrap>", line 222, in _call_with_frames_removed
  File "/app/apps/home/context_processors.py", line 14, in <module>
    raise Exception('failed to read %s. was frontend built?' % assets_json_fname)
Exception: failed to read /static/assets.json. was frontend built?
Internal Server Error: /
Traceback (most recent call last):
  File "/app/context_processors.py", line 11, in <module>
    static_assets = json.load(f.read())['main']
  File "/usr/local/lib/python3.5/json/__init__.py", line 265, in load
    return loads(fp.read(),
AttributeError: 'str' object has no attribute 'read'

During handling of the above exception, another exception occurred:

Traceback (most recent call last):
  File "/usr/local/lib/python3.5/site-packages/django/core/handlers/base.py", line 149, in get_response
    response = self.process_exception_by_middleware(e, request)
  File "/usr/local/lib/python3.5/site-packages/django/core/handlers/base.py", line 147, in get_response
    response = wrapped_callback(request, *callback_args, **callback_kwargs)
  File "/app/apps/home/views.py", line 4, in index
    return render(request, 'home/index.html')
  File "/usr/local/lib/python3.5/site-packages/django/shortcuts.py", line 67, in render
    template_name, context, request=request, using=using)
  File "/usr/local/lib/python3.5/site-packages/django/template/loader.py", line 97, in render_to_string
    return template.render(context, request)
  File "/usr/local/lib/python3.5/site-packages/django/template/backends/django.py", line 95, in render
    return self.template.render(context)
  File "/usr/local/lib/python3.5/site-packages/django/template/base.py", line 204, in render
    with context.bind_template(self):
  File "/usr/local/lib/python3.5/contextlib.py", line 59, in __enter__
    return next(self.gen)
  File "/usr/local/lib/python3.5/site-packages/django/template/context.py", line 256, in bind_template
    processors = (template.engine.template_context_processors +
  File "/usr/local/lib/python3.5/site-packages/django/utils/functional.py", line 33, in __get__
    res = instance.__dict__[self.name] = self.func(instance)
  File "/usr/local/lib/python3.5/site-packages/django/template/engine.py", line 105, in template_context_processors
    return tuple(import_string(path) for path in context_processors)
  File "/usr/local/lib/python3.5/site-packages/django/template/engine.py", line 105, in <genexpr>
    return tuple(import_string(path) for path in context_processors)
  File "/usr/local/lib/python3.5/site-packages/django/utils/module_loading.py", line 20, in import_string
    module = import_module(module_path)
  File "/usr/local/lib/python3.5/importlib/__init__.py", line 126, in import_module
    return _bootstrap._gcd_import(name[level:], package, level)
  File "<frozen importlib._bootstrap>", line 986, in _gcd_import
  File "<frozen importlib._bootstrap>", line 969, in _find_and_load
  File "<frozen importlib._bootstrap>", line 958, in _find_and_load_unlocked
  File "<frozen importlib._bootstrap>", line 673, in _load_unlocked
  File "<frozen importlib._bootstrap_external>", line 662, in exec_module
  File "<frozen importlib._bootstrap>", line 222, in _call_with_frames_removed
  File "/app/context_processors.py", line 13, in <module>
    raise Exception('failed to read %s. was frontend built?' % assets_json_fname)
Exception: failed to read /app/assets.json. was frontend built?
Internal Server Error: /favicon.ico
Traceback (most recent call last):
  File "/app/context_processors.py", line 11, in <module>
    static_assets = json.load(f.read())['main']
  File "/usr/local/lib/python3.5/json/__init__.py", line 265, in load
    return loads(fp.read(),
AttributeError: 'str' object has no attribute 'read'

During handling of the above exception, another exception occurred:

Traceback (most recent call last):
  File "/usr/local/lib/python3.5/site-packages/django/core/handlers/base.py", line 149, in get_response
    response = self.process_exception_by_middleware(e, request)
  File "/usr/local/lib/python3.5/site-packages/django/core/handlers/base.py", line 147, in get_response
    response = wrapped_callback(request, *callback_args, **callback_kwargs)
  File "/app/apps/home/views.py", line 4, in index
    return render(request, 'home/index.html')
  File "/usr/local/lib/python3.5/site-packages/django/shortcuts.py", line 67, in render
    template_name, context, request=request, using=using)
  File "/usr/local/lib/python3.5/site-packages/django/template/loader.py", line 97, in render_to_string
    return template.render(context, request)
  File "/usr/local/lib/python3.5/site-packages/django/template/backends/django.py", line 95, in render
    return self.template.render(context)
  File "/usr/local/lib/python3.5/site-packages/django/template/base.py", line 204, in render
    with context.bind_template(self):
  File "/usr/local/lib/python3.5/contextlib.py", line 59, in __enter__
    return next(self.gen)
  File "/usr/local/lib/python3.5/site-packages/django/template/context.py", line 256, in bind_template
    processors = (template.engine.template_context_processors +
  File "/usr/local/lib/python3.5/site-packages/django/utils/functional.py", line 33, in __get__
    res = instance.__dict__[self.name] = self.func(instance)
  File "/usr/local/lib/python3.5/site-packages/django/template/engine.py", line 105, in template_context_processors
    return tuple(import_string(path) for path in context_processors)
  File "/usr/local/lib/python3.5/site-packages/django/template/engine.py", line 105, in <genexpr>
    return tuple(import_string(path) for path in context_processors)
  File "/usr/local/lib/python3.5/site-packages/django/utils/module_loading.py", line 20, in import_string
    module = import_module(module_path)
  File "/usr/local/lib/python3.5/importlib/__init__.py", line 126, in import_module
    return _bootstrap._gcd_import(name[level:], package, level)
  File "<frozen importlib._bootstrap>", line 986, in _gcd_import
  File "<frozen importlib._bootstrap>", line 969, in _find_and_load
  File "<frozen importlib._bootstrap>", line 958, in _find_and_load_unlocked
  File "<frozen importlib._bootstrap>", line 673, in _load_unlocked
  File "<frozen importlib._bootstrap_external>", line 662, in exec_module
  File "<frozen importlib._bootstrap>", line 222, in _call_with_frames_removed
  File "/app/context_processors.py", line 13, in <module>
    raise Exception('failed to read %s. was frontend built?' % assets_json_fname)
Exception: failed to read /app/assets.json. was frontend built?
