[2016-04-03 09:41:16 +0000] [17] [INFO] Starting gunicorn 19.4.5
[2016-04-03 09:41:16 +0000] [17] [INFO] Listening at: http://0.0.0.0:8000 (17)
[2016-04-03 09:41:16 +0000] [17] [INFO] Using worker: sync
[2016-04-03 09:41:16 +0000] [20] [INFO] Booting worker with pid: 20
[2016-04-03 09:41:16 +0000] [21] [INFO] Booting worker with pid: 21
[2016-04-03 09:41:16 +0000] [23] [INFO] Booting worker with pid: 23
[2016-04-03 09:41:16 +0000] [25] [INFO] Booting worker with pid: 25
[2016-04-03 09:41:16 +0000] [27] [INFO] Booting worker with pid: 27
[2016-04-03 09:41:16 +0000] [28] [INFO] Booting worker with pid: 28
[2016-04-03 09:41:16 +0000] [30] [INFO] Booting worker with pid: 30
[2016-04-03 09:41:16 +0000] [31] [INFO] Booting worker with pid: 31
[2016-04-03 09:41:16 +0000] [34] [INFO] Booting worker with pid: 34
[2016-04-03 09:42:57 +0000] [18] [INFO] Starting gunicorn 19.4.5
[2016-04-03 09:42:57 +0000] [18] [INFO] Listening at: http://0.0.0.0:8000 (18)
[2016-04-03 09:42:57 +0000] [18] [INFO] Using worker: sync
[2016-04-03 09:42:57 +0000] [21] [INFO] Booting worker with pid: 21
[2016-04-03 09:42:57 +0000] [22] [INFO] Booting worker with pid: 22
[2016-04-03 09:42:57 +0000] [23] [INFO] Booting worker with pid: 23
[2016-04-03 09:42:57 +0000] [27] [INFO] Booting worker with pid: 27
[2016-04-03 09:42:57 +0000] [28] [INFO] Booting worker with pid: 28
[2016-04-03 09:42:57 +0000] [29] [INFO] Booting worker with pid: 29
[2016-04-03 09:42:57 +0000] [30] [INFO] Booting worker with pid: 30
[2016-04-03 09:42:57 +0000] [31] [INFO] Booting worker with pid: 31
[2016-04-03 09:42:57 +0000] [35] [INFO] Booting worker with pid: 35
[2016-04-05 17:52:16 +0000] [8] [INFO] Starting gunicorn 19.4.5
[2016-04-05 17:52:16 +0000] [8] [INFO] Listening at: http://0.0.0.0:8000 (8)
[2016-04-05 17:52:16 +0000] [8] [INFO] Using worker: sync
[2016-04-05 17:52:16 +0000] [11] [INFO] Booting worker with pid: 11
[2016-04-05 17:52:16 +0000] [12] [INFO] Booting worker with pid: 12
[2016-04-05 17:52:16 +0000] [13] [INFO] Booting worker with pid: 13
[2016-04-05 17:52:16 +0000] [14] [INFO] Booting worker with pid: 14
[2016-04-05 17:52:16 +0000] [16] [INFO] Booting worker with pid: 16
[2016-04-05 17:52:16 +0000] [20] [INFO] Booting worker with pid: 20
[2016-04-05 17:52:16 +0000] [23] [INFO] Booting worker with pid: 23
[2016-04-05 17:52:16 +0000] [11] [ERROR] Exception in worker process:
Traceback (most recent call last):
  File "/usr/local/lib/python3.5/site-packages/gunicorn/arbiter.py", line 515, in spawn_worker
    worker.init_process()
  File "/usr/local/lib/python3.5/site-packages/gunicorn/workers/base.py", line 122, in init_process
    self.load_wsgi()
  File "/usr/local/lib/python3.5/site-packages/gunicorn/workers/base.py", line 130, in load_wsgi
    self.wsgi = self.app.wsgi()
  File "/usr/local/lib/python3.5/site-packages/gunicorn/app/base.py", line 67, in wsgi
    self.callable = self.load()
  File "/usr/local/lib/python3.5/site-packages/gunicorn/app/wsgiapp.py", line 65, in load
    return self.load_wsgiapp()
  File "/usr/local/lib/python3.5/site-packages/gunicorn/app/wsgiapp.py", line 52, in load_wsgiapp
    return util.import_app(self.app_uri)
  File "/usr/local/lib/python3.5/site-packages/gunicorn/util.py", line 357, in import_app
    __import__(module)
  File "/app/wsgi.py", line 16, in <module>
    application = get_wsgi_application()
  File "/usr/local/lib/python3.5/site-packages/django/core/wsgi.py", line 13, in get_wsgi_application
    django.setup()
  File "/usr/local/lib/python3.5/site-packages/django/__init__.py", line 17, in setup
    configure_logging(settings.LOGGING_CONFIG, settings.LOGGING)
  File "/usr/local/lib/python3.5/site-packages/django/conf/__init__.py", line 55, in __getattr__
    self._setup(name)
  File "/usr/local/lib/python3.5/site-packages/django/conf/__init__.py", line 43, in _setup
    self._wrapped = Settings(settings_module)
  File "/usr/local/lib/python3.5/site-packages/django/conf/__init__.py", line 99, in __init__
    mod = importlib.import_module(self.SETTINGS_MODULE)
  File "/usr/local/lib/python3.5/importlib/__init__.py", line 126, in import_module
    return _bootstrap._gcd_import(name[level:], package, level)
ImportError: No module named 'conf'
Traceback (most recent call last):
  File "/usr/local/lib/python3.5/site-packages/gunicorn/arbiter.py", line 515, in spawn_worker
    worker.init_process()
  File "/usr/local/lib/python3.5/site-packages/gunicorn/workers/base.py", line 122, in init_process
    self.load_wsgi()
  File "/usr/local/lib/python3.5/site-packages/gunicorn/workers/base.py", line 130, in load_wsgi
    self.wsgi = self.app.wsgi()
  File "/usr/local/lib/python3.5/site-packages/gunicorn/app/base.py", line 67, in wsgi
    self.callable = self.load()
  File "/usr/local/lib/python3.5/site-packages/gunicorn/app/wsgiapp.py", line 65, in load
    return self.load_wsgiapp()
  File "/usr/local/lib/python3.5/site-packages/gunicorn/app/wsgiapp.py", line 52, in load_wsgiapp
    return util.import_app(self.app_uri)
  File "/usr/local/lib/python3.5/site-packages/gunicorn/util.py", line 357, in import_app
    __import__(module)
  File "/app/wsgi.py", line 16, in <module>
    application = get_wsgi_application()
  File "/usr/local/lib/python3.5/site-packages/django/core/wsgi.py", line 13, in get_wsgi_application
    django.setup()
  File "/usr/local/lib/python3.5/site-packages/django/__init__.py", line 17, in setup
    configure_logging(settings.LOGGING_CONFIG, settings.LOGGING)
  File "/usr/local/lib/python3.5/site-packages/django/conf/__init__.py", line 55, in __getattr__
    self._setup(name)
  File "/usr/local/lib/python3.5/site-packages/django/conf/__init__.py", line 43, in _setup
    self._wrapped = Settings(settings_module)
  File "/usr/local/lib/python3.5/site-packages/django/conf/__init__.py", line 99, in __init__
    mod = importlib.import_module(self.SETTINGS_MODULE)
  File "/usr/local/lib/python3.5/importlib/__init__.py", line 126, in import_module
    return _bootstrap._gcd_import(name[level:], package, level)
ImportError: No module named 'conf'
[2016-04-05 17:52:16 +0000] [11] [INFO] Worker exiting (pid: 11)
[2016-04-05 17:52:16 +0000] [24] [INFO] Booting worker with pid: 24
[2016-04-05 17:52:16 +0000] [13] [ERROR] Exception in worker process:
Traceback (most recent call last):
  File "/usr/local/lib/python3.5/site-packages/gunicorn/arbiter.py", line 515, in spawn_worker
    worker.init_process()
  File "/usr/local/lib/python3.5/site-packages/gunicorn/workers/base.py", line 122, in init_process
    self.load_wsgi()
  File "/usr/local/lib/python3.5/site-packages/gunicorn/workers/base.py", line 130, in load_wsgi
    self.wsgi = self.app.wsgi()
  File "/usr/local/lib/python3.5/site-packages/gunicorn/app/base.py", line 67, in wsgi
    self.callable = self.load()
  File "/usr/local/lib/python3.5/site-packages/gunicorn/app/wsgiapp.py", line 65, in load
    return self.load_wsgiapp()
  File "/usr/local/lib/python3.5/site-packages/gunicorn/app/wsgiapp.py", line 52, in load_wsgiapp
    return util.import_app(self.app_uri)
  File "/usr/local/lib/python3.5/site-packages/gunicorn/util.py", line 357, in import_app
    __import__(module)
  File "/app/wsgi.py", line 16, in <module>
    application = get_wsgi_application()
  File "/usr/local/lib/python3.5/site-packages/django/core/wsgi.py", line 13, in get_wsgi_application
    django.setup()
  File "/usr/local/lib/python3.5/site-packages/django/__init__.py", line 17, in setup
    configure_logging(settings.LOGGING_CONFIG, settings.LOGGING)
  File "/usr/local/lib/python3.5/site-packages/django/conf/__init__.py", line 55, in __getattr__
    self._setup(name)
  File "/usr/local/lib/python3.5/site-packages/django/conf/__init__.py", line 43, in _setup
    self._wrapped = Settings(settings_module)
  File "/usr/local/lib/python3.5/site-packages/django/conf/__init__.py", line 99, in __init__
    mod = importlib.import_module(self.SETTINGS_MODULE)
  File "/usr/local/lib/python3.5/importlib/__init__.py", line 126, in import_module
    return _bootstrap._gcd_import(name[level:], package, level)
ImportError: No module named 'conf'
Traceback (most recent call last):
  File "/usr/local/lib/python3.5/site-packages/gunicorn/arbiter.py", line 515, in spawn_worker
    worker.init_process()
  File "/usr/local/lib/python3.5/site-packages/gunicorn/workers/base.py", line 122, in init_process
    self.load_wsgi()
  File "/usr/local/lib/python3.5/site-packages/gunicorn/workers/base.py", line 130, in load_wsgi
    self.wsgi = self.app.wsgi()
  File "/usr/local/lib/python3.5/site-packages/gunicorn/app/base.py", line 67, in wsgi
    self.callable = self.load()
  File "/usr/local/lib/python3.5/site-packages/gunicorn/app/wsgiapp.py", line 65, in load
    return self.load_wsgiapp()
  File "/usr/local/lib/python3.5/site-packages/gunicorn/app/wsgiapp.py", line 52, in load_wsgiapp
    return util.import_app(self.app_uri)
  File "/usr/local/lib/python3.5/site-packages/gunicorn/util.py", line 357, in import_app
    __import__(module)
  File "/app/wsgi.py", line 16, in <module>
    application = get_wsgi_application()
  File "/usr/local/lib/python3.5/site-packages/django/core/wsgi.py", line 13, in get_wsgi_application
    django.setup()
  File "/usr/local/lib/python3.5/site-packages/django/__init__.py", line 17, in setup
    configure_logging(settings.LOGGING_CONFIG, settings.LOGGING)
  File "/usr/local/lib/python3.5/site-packages/django/conf/__init__.py", line 55, in __getattr__
    self._setup(name)
  File "/usr/local/lib/python3.5/site-packages/django/conf/__init__.py", line 43, in _setup
    self._wrapped = Settings(settings_module)
  File "/usr/local/lib/python3.5/site-packages/django/conf/__init__.py", line 99, in __init__
    mod = importlib.import_module(self.SETTINGS_MODULE)
  File "/usr/local/lib/python3.5/importlib/__init__.py", line 126, in import_module
    return _bootstrap._gcd_import(name[level:], package, level)
ImportError: No module named 'conf'
[2016-04-05 17:52:16 +0000] [13] [INFO] Worker exiting (pid: 13)
[2016-04-05 17:52:16 +0000] [25] [INFO] Booting worker with pid: 25
[2016-04-05 17:52:16 +0000] [14] [ERROR] Exception in worker process:
Traceback (most recent call last):
  File "/usr/local/lib/python3.5/site-packages/gunicorn/arbiter.py", line 515, in spawn_worker
    worker.init_process()
  File "/usr/local/lib/python3.5/site-packages/gunicorn/workers/base.py", line 122, in init_process
    self.load_wsgi()
  File "/usr/local/lib/python3.5/site-packages/gunicorn/workers/base.py", line 130, in load_wsgi
    self.wsgi = self.app.wsgi()
  File "/usr/local/lib/python3.5/site-packages/gunicorn/app/base.py", line 67, in wsgi
    self.callable = self.load()
  File "/usr/local/lib/python3.5/site-packages/gunicorn/app/wsgiapp.py", line 65, in load
    return self.load_wsgiapp()
  File "/usr/local/lib/python3.5/site-packages/gunicorn/app/wsgiapp.py", line 52, in load_wsgiapp
    return util.import_app(self.app_uri)
  File "/usr/local/lib/python3.5/site-packages/gunicorn/util.py", line 357, in import_app
    __import__(module)
  File "/app/wsgi.py", line 16, in <module>
    application = get_wsgi_application()
  File "/usr/local/lib/python3.5/site-packages/django/core/wsgi.py", line 13, in get_wsgi_application
    django.setup()
  File "/usr/local/lib/python3.5/site-packages/django/__init__.py", line 17, in setup
    configure_logging(settings.LOGGING_CONFIG, settings.LOGGING)
  File "/usr/local/lib/python3.5/site-packages/django/conf/__init__.py", line 55, in __getattr__
    self._setup(name)
  File "/usr/local/lib/python3.5/site-packages/django/conf/__init__.py", line 43, in _setup
    self._wrapped = Settings(settings_module)
  File "/usr/local/lib/python3.5/site-packages/django/conf/__init__.py", line 99, in __init__
    mod = importlib.import_module(self.SETTINGS_MODULE)
  File "/usr/local/lib/python3.5/importlib/__init__.py", line 126, in import_module
    return _bootstrap._gcd_import(name[level:], package, level)
ImportError: No module named 'conf'
Traceback (most recent call last):
  File "/usr/local/lib/python3.5/site-packages/gunicorn/arbiter.py", line 515, in spawn_worker
    worker.init_process()
  File "/usr/local/lib/python3.5/site-packages/gunicorn/workers/base.py", line 122, in init_process
    self.load_wsgi()
  File "/usr/local/lib/python3.5/site-packages/gunicorn/workers/base.py", line 130, in load_wsgi
    self.wsgi = self.app.wsgi()
  File "/usr/local/lib/python3.5/site-packages/gunicorn/app/base.py", line 67, in wsgi
    self.callable = self.load()
  File "/usr/local/lib/python3.5/site-packages/gunicorn/app/wsgiapp.py", line 65, in load
    return self.load_wsgiapp()
  File "/usr/local/lib/python3.5/site-packages/gunicorn/app/wsgiapp.py", line 52, in load_wsgiapp
    return util.import_app(self.app_uri)
  File "/usr/local/lib/python3.5/site-packages/gunicorn/util.py", line 357, in import_app
    __import__(module)
  File "/app/wsgi.py", line 16, in <module>
    application = get_wsgi_application()
  File "/usr/local/lib/python3.5/site-packages/django/core/wsgi.py", line 13, in get_wsgi_application
    django.setup()
  File "/usr/local/lib/python3.5/site-packages/django/__init__.py", line 17, in setup
    configure_logging(settings.LOGGING_CONFIG, settings.LOGGING)
  File "/usr/local/lib/python3.5/site-packages/django/conf/__init__.py", line 55, in __getattr__
    self._setup(name)
  File "/usr/local/lib/python3.5/site-packages/django/conf/__init__.py", line 43, in _setup
    self._wrapped = Settings(settings_module)
  File "/usr/local/lib/python3.5/site-packages/django/conf/__init__.py", line 99, in __init__
    mod = importlib.import_module(self.SETTINGS_MODULE)
  File "/usr/local/lib/python3.5/importlib/__init__.py", line 126, in import_module
    return _bootstrap._gcd_import(name[level:], package, level)
ImportError: No module named 'conf'
[2016-04-05 17:52:16 +0000] [14] [INFO] Worker exiting (pid: 14)
[2016-04-05 17:52:17 +0000] [12] [ERROR] Exception in worker process:
Traceback (most recent call last):
  File "/usr/local/lib/python3.5/site-packages/gunicorn/arbiter.py", line 515, in spawn_worker
    worker.init_process()
  File "/usr/local/lib/python3.5/site-packages/gunicorn/workers/base.py", line 122, in init_process
    self.load_wsgi()
  File "/usr/local/lib/python3.5/site-packages/gunicorn/workers/base.py", line 130, in load_wsgi
    self.wsgi = self.app.wsgi()
  File "/usr/local/lib/python3.5/site-packages/gunicorn/app/base.py", line 67, in wsgi
    self.callable = self.load()
  File "/usr/local/lib/python3.5/site-packages/gunicorn/app/wsgiapp.py", line 65, in load
    return self.load_wsgiapp()
  File "/usr/local/lib/python3.5/site-packages/gunicorn/app/wsgiapp.py", line 52, in load_wsgiapp
    return util.import_app(self.app_uri)
  File "/usr/local/lib/python3.5/site-packages/gunicorn/util.py", line 357, in import_app
    __import__(module)
  File "/app/wsgi.py", line 16, in <module>
    application = get_wsgi_application()
  File "/usr/local/lib/python3.5/site-packages/django/core/wsgi.py", line 13, in get_wsgi_application
    django.setup()
  File "/usr/local/lib/python3.5/site-packages/django/__init__.py", line 17, in setup
    configure_logging(settings.LOGGING_CONFIG, settings.LOGGING)
  File "/usr/local/lib/python3.5/site-packages/django/conf/__init__.py", line 55, in __getattr__
    self._setup(name)
  File "/usr/local/lib/python3.5/site-packages/django/conf/__init__.py", line 43, in _setup
    self._wrapped = Settings(settings_module)
  File "/usr/local/lib/python3.5/site-packages/django/conf/__init__.py", line 99, in __init__
    mod = importlib.import_module(self.SETTINGS_MODULE)
  File "/usr/local/lib/python3.5/importlib/__init__.py", line 126, in import_module
    return _bootstrap._gcd_import(name[level:], package, level)
ImportError: No module named 'conf'
Traceback (most recent call last):
  File "/usr/local/lib/python3.5/site-packages/gunicorn/arbiter.py", line 515, in spawn_worker
    worker.init_process()
  File "/usr/local/lib/python3.5/site-packages/gunicorn/workers/base.py", line 122, in init_process
    self.load_wsgi()
  File "/usr/local/lib/python3.5/site-packages/gunicorn/workers/base.py", line 130, in load_wsgi
    self.wsgi = self.app.wsgi()
  File "/usr/local/lib/python3.5/site-packages/gunicorn/app/base.py", line 67, in wsgi
    self.callable = self.load()
  File "/usr/local/lib/python3.5/site-packages/gunicorn/app/wsgiapp.py", line 65, in load
    return self.load_wsgiapp()
  File "/usr/local/lib/python3.5/site-packages/gunicorn/app/wsgiapp.py", line 52, in load_wsgiapp
    return util.import_app(self.app_uri)
  File "/usr/local/lib/python3.5/site-packages/gunicorn/util.py", line 357, in import_app
    __import__(module)
  File "/app/wsgi.py", line 16, in <module>
    application = get_wsgi_application()
  File "/usr/local/lib/python3.5/site-packages/django/core/wsgi.py", line 13, in get_wsgi_application
    django.setup()
  File "/usr/local/lib/python3.5/site-packages/django/__init__.py", line 17, in setup
    configure_logging(settings.LOGGING_CONFIG, settings.LOGGING)
  File "/usr/local/lib/python3.5/site-packages/django/conf/__init__.py", line 55, in __getattr__
    self._setup(name)
  File "/usr/local/lib/python3.5/site-packages/django/conf/__init__.py", line 43, in _setup
    self._wrapped = Settings(settings_module)
  File "/usr/local/lib/python3.5/site-packages/django/conf/__init__.py", line 99, in __init__
    mod = importlib.import_module(self.SETTINGS_MODULE)
  File "/usr/local/lib/python3.5/importlib/__init__.py", line 126, in import_module
    return _bootstrap._gcd_import(name[level:], package, level)
ImportError: No module named 'conf'
[2016-04-05 17:52:17 +0000] [12] [INFO] Worker exiting (pid: 12)
[2016-04-05 17:52:17 +0000] [16] [ERROR] Exception in worker process:
Traceback (most recent call last):
  File "/usr/local/lib/python3.5/site-packages/gunicorn/arbiter.py", line 515, in spawn_worker
    worker.init_process()
  File "/usr/local/lib/python3.5/site-packages/gunicorn/workers/base.py", line 122, in init_process
    self.load_wsgi()
  File "/usr/local/lib/python3.5/site-packages/gunicorn/workers/base.py", line 130, in load_wsgi
    self.wsgi = self.app.wsgi()
  File "/usr/local/lib/python3.5/site-packages/gunicorn/app/base.py", line 67, in wsgi
    self.callable = self.load()
  File "/usr/local/lib/python3.5/site-packages/gunicorn/app/wsgiapp.py", line 65, in load
    return self.load_wsgiapp()
  File "/usr/local/lib/python3.5/site-packages/gunicorn/app/wsgiapp.py", line 52, in load_wsgiapp
    return util.import_app(self.app_uri)
  File "/usr/local/lib/python3.5/site-packages/gunicorn/util.py", line 357, in import_app
    __import__(module)
  File "/app/wsgi.py", line 16, in <module>
    application = get_wsgi_application()
  File "/usr/local/lib/python3.5/site-packages/django/core/wsgi.py", line 13, in get_wsgi_application
    django.setup()
  File "/usr/local/lib/python3.5/site-packages/django/__init__.py", line 17, in setup
    configure_logging(settings.LOGGING_CONFIG, settings.LOGGING)
  File "/usr/local/lib/python3.5/site-packages/django/conf/__init__.py", line 55, in __getattr__
    self._setup(name)
  File "/usr/local/lib/python3.5/site-packages/django/conf/__init__.py", line 43, in _setup
    self._wrapped = Settings(settings_module)
  File "/usr/local/lib/python3.5/site-packages/django/conf/__init__.py", line 99, in __init__
    mod = importlib.import_module(self.SETTINGS_MODULE)
  File "/usr/local/lib/python3.5/importlib/__init__.py", line 126, in import_module
    return _bootstrap._gcd_import(name[level:], package, level)
ImportError: No module named 'conf'
Traceback (most recent call last):
  File "/usr/local/lib/python3.5/site-packages/gunicorn/arbiter.py", line 515, in spawn_worker
    worker.init_process()
  File "/usr/local/lib/python3.5/site-packages/gunicorn/workers/base.py", line 122, in init_process
    self.load_wsgi()
  File "/usr/local/lib/python3.5/site-packages/gunicorn/workers/base.py", line 130, in load_wsgi
    self.wsgi = self.app.wsgi()
  File "/usr/local/lib/python3.5/site-packages/gunicorn/app/base.py", line 67, in wsgi
    self.callable = self.load()
  File "/usr/local/lib/python3.5/site-packages/gunicorn/app/wsgiapp.py", line 65, in load
    return self.load_wsgiapp()
  File "/usr/local/lib/python3.5/site-packages/gunicorn/app/wsgiapp.py", line 52, in load_wsgiapp
    return util.import_app(self.app_uri)
  File "/usr/local/lib/python3.5/site-packages/gunicorn/util.py", line 357, in import_app
    __import__(module)
  File "/app/wsgi.py", line 16, in <module>
    application = get_wsgi_application()
  File "/usr/local/lib/python3.5/site-packages/django/core/wsgi.py", line 13, in get_wsgi_application
    django.setup()
  File "/usr/local/lib/python3.5/site-packages/django/__init__.py", line 17, in setup
    configure_logging(settings.LOGGING_CONFIG, settings.LOGGING)
  File "/usr/local/lib/python3.5/site-packages/django/conf/__init__.py", line 55, in __getattr__
    self._setup(name)
  File "/usr/local/lib/python3.5/site-packages/django/conf/__init__.py", line 43, in _setup
    self._wrapped = Settings(settings_module)
  File "/usr/local/lib/python3.5/site-packages/django/conf/__init__.py", line 99, in __init__
    mod = importlib.import_module(self.SETTINGS_MODULE)
  File "/usr/local/lib/python3.5/importlib/__init__.py", line 126, in import_module
    return _bootstrap._gcd_import(name[level:], package, level)
ImportError: No module named 'conf'
[2016-04-05 17:52:17 +0000] [16] [INFO] Worker exiting (pid: 16)
[2016-04-05 17:52:17 +0000] [20] [ERROR] Exception in worker process:
Traceback (most recent call last):
  File "/usr/local/lib/python3.5/site-packages/gunicorn/arbiter.py", line 515, in spawn_worker
    worker.init_process()
  File "/usr/local/lib/python3.5/site-packages/gunicorn/workers/base.py", line 122, in init_process
    self.load_wsgi()
  File "/usr/local/lib/python3.5/site-packages/gunicorn/workers/base.py", line 130, in load_wsgi
    self.wsgi = self.app.wsgi()
  File "/usr/local/lib/python3.5/site-packages/gunicorn/app/base.py", line 67, in wsgi
    self.callable = self.load()
  File "/usr/local/lib/python3.5/site-packages/gunicorn/app/wsgiapp.py", line 65, in load
    return self.load_wsgiapp()
  File "/usr/local/lib/python3.5/site-packages/gunicorn/app/wsgiapp.py", line 52, in load_wsgiapp
    return util.import_app(self.app_uri)
  File "/usr/local/lib/python3.5/site-packages/gunicorn/util.py", line 357, in import_app
    __import__(module)
  File "/app/wsgi.py", line 16, in <module>
    application = get_wsgi_application()
  File "/usr/local/lib/python3.5/site-packages/django/core/wsgi.py", line 13, in get_wsgi_application
    django.setup()
  File "/usr/local/lib/python3.5/site-packages/django/__init__.py", line 17, in setup
    configure_logging(settings.LOGGING_CONFIG, settings.LOGGING)
  File "/usr/local/lib/python3.5/site-packages/django/conf/__init__.py", line 55, in __getattr__
    self._setup(name)
  File "/usr/local/lib/python3.5/site-packages/django/conf/__init__.py", line 43, in _setup
    self._wrapped = Settings(settings_module)
  File "/usr/local/lib/python3.5/site-packages/django/conf/__init__.py", line 99, in __init__
    mod = importlib.import_module(self.SETTINGS_MODULE)
  File "/usr/local/lib/python3.5/importlib/__init__.py", line 126, in import_module
    return _bootstrap._gcd_import(name[level:], package, level)
ImportError: No module named 'conf'
Traceback (most recent call last):
  File "/usr/local/lib/python3.5/site-packages/gunicorn/arbiter.py", line 515, in spawn_worker
    worker.init_process()
  File "/usr/local/lib/python3.5/site-packages/gunicorn/workers/base.py", line 122, in init_process
    self.load_wsgi()
  File "/usr/local/lib/python3.5/site-packages/gunicorn/workers/base.py", line 130, in load_wsgi
    self.wsgi = self.app.wsgi()
  File "/usr/local/lib/python3.5/site-packages/gunicorn/app/base.py", line 67, in wsgi
    self.callable = self.load()
  File "/usr/local/lib/python3.5/site-packages/gunicorn/app/wsgiapp.py", line 65, in load
    return self.load_wsgiapp()
  File "/usr/local/lib/python3.5/site-packages/gunicorn/app/wsgiapp.py", line 52, in load_wsgiapp
    return util.import_app(self.app_uri)
  File "/usr/local/lib/python3.5/site-packages/gunicorn/util.py", line 357, in import_app
    __import__(module)
  File "/app/wsgi.py", line 16, in <module>
    application = get_wsgi_application()
  File "/usr/local/lib/python3.5/site-packages/django/core/wsgi.py", line 13, in get_wsgi_application
    django.setup()
  File "/usr/local/lib/python3.5/site-packages/django/__init__.py", line 17, in setup
    configure_logging(settings.LOGGING_CONFIG, settings.LOGGING)
  File "/usr/local/lib/python3.5/site-packages/django/conf/__init__.py", line 55, in __getattr__
    self._setup(name)
  File "/usr/local/lib/python3.5/site-packages/django/conf/__init__.py", line 43, in _setup
    self._wrapped = Settings(settings_module)
  File "/usr/local/lib/python3.5/site-packages/django/conf/__init__.py", line 99, in __init__
    mod = importlib.import_module(self.SETTINGS_MODULE)
  File "/usr/local/lib/python3.5/importlib/__init__.py", line 126, in import_module
    return _bootstrap._gcd_import(name[level:], package, level)
ImportError: No module named 'conf'
[2016-04-05 17:52:17 +0000] [20] [INFO] Worker exiting (pid: 20)
[2016-04-05 17:57:09 +0000] [9] [INFO] Starting gunicorn 19.4.5
[2016-04-05 17:57:09 +0000] [9] [INFO] Listening at: http://0.0.0.0:8000 (9)
[2016-04-05 17:57:09 +0000] [9] [INFO] Using worker: sync
[2016-04-05 17:57:09 +0000] [12] [INFO] Booting worker with pid: 12
[2016-04-05 17:57:09 +0000] [12] [ERROR] Exception in worker process:
Traceback (most recent call last):
  File "/usr/local/lib/python3.5/site-packages/gunicorn/arbiter.py", line 515, in spawn_worker
    worker.init_process()
  File "/usr/local/lib/python3.5/site-packages/gunicorn/workers/base.py", line 122, in init_process
    self.load_wsgi()
  File "/usr/local/lib/python3.5/site-packages/gunicorn/workers/base.py", line 130, in load_wsgi
    self.wsgi = self.app.wsgi()
  File "/usr/local/lib/python3.5/site-packages/gunicorn/app/base.py", line 67, in wsgi
    self.callable = self.load()
  File "/usr/local/lib/python3.5/site-packages/gunicorn/app/wsgiapp.py", line 65, in load
    return self.load_wsgiapp()
  File "/usr/local/lib/python3.5/site-packages/gunicorn/app/wsgiapp.py", line 52, in load_wsgiapp
    return util.import_app(self.app_uri)
  File "/usr/local/lib/python3.5/site-packages/gunicorn/util.py", line 357, in import_app
    __import__(module)
ImportError: No module named 'app'
Traceback (most recent call last):
  File "/usr/local/lib/python3.5/site-packages/gunicorn/arbiter.py", line 515, in spawn_worker
    worker.init_process()
  File "/usr/local/lib/python3.5/site-packages/gunicorn/workers/base.py", line 122, in init_process
    self.load_wsgi()
  File "/usr/local/lib/python3.5/site-packages/gunicorn/workers/base.py", line 130, in load_wsgi
    self.wsgi = self.app.wsgi()
  File "/usr/local/lib/python3.5/site-packages/gunicorn/app/base.py", line 67, in wsgi
    self.callable = self.load()
  File "/usr/local/lib/python3.5/site-packages/gunicorn/app/wsgiapp.py", line 65, in load
    return self.load_wsgiapp()
  File "/usr/local/lib/python3.5/site-packages/gunicorn/app/wsgiapp.py", line 52, in load_wsgiapp
    return util.import_app(self.app_uri)
  File "/usr/local/lib/python3.5/site-packages/gunicorn/util.py", line 357, in import_app
    __import__(module)
ImportError: No module named 'app'
[2016-04-05 17:57:09 +0000] [12] [INFO] Worker exiting (pid: 12)
[2016-04-05 17:57:09 +0000] [9] [INFO] Shutting down: Master
[2016-04-05 17:57:09 +0000] [9] [INFO] Reason: Worker failed to boot.
[2016-04-05 18:00:32 +0000] [10] [INFO] Starting gunicorn 19.4.5
[2016-04-05 18:00:32 +0000] [10] [INFO] Listening at: http://0.0.0.0:8000 (10)
[2016-04-05 18:00:32 +0000] [10] [INFO] Using worker: sync
[2016-04-05 18:00:32 +0000] [13] [INFO] Booting worker with pid: 13
[2016-04-05 18:00:32 +0000] [13] [ERROR] Exception in worker process:
Traceback (most recent call last):
  File "/usr/local/lib/python3.5/site-packages/gunicorn/arbiter.py", line 515, in spawn_worker
    worker.init_process()
  File "/usr/local/lib/python3.5/site-packages/gunicorn/workers/base.py", line 122, in init_process
    self.load_wsgi()
  File "/usr/local/lib/python3.5/site-packages/gunicorn/workers/base.py", line 130, in load_wsgi
    self.wsgi = self.app.wsgi()
  File "/usr/local/lib/python3.5/site-packages/gunicorn/app/base.py", line 67, in wsgi
    self.callable = self.load()
  File "/usr/local/lib/python3.5/site-packages/gunicorn/app/wsgiapp.py", line 65, in load
    return self.load_wsgiapp()
  File "/usr/local/lib/python3.5/site-packages/gunicorn/app/wsgiapp.py", line 52, in load_wsgiapp
    return util.import_app(self.app_uri)
  File "/usr/local/lib/python3.5/site-packages/gunicorn/util.py", line 357, in import_app
    __import__(module)
ImportError: No module named 'app'
Traceback (most recent call last):
  File "/usr/local/lib/python3.5/site-packages/gunicorn/arbiter.py", line 515, in spawn_worker
    worker.init_process()
  File "/usr/local/lib/python3.5/site-packages/gunicorn/workers/base.py", line 122, in init_process
    self.load_wsgi()
  File "/usr/local/lib/python3.5/site-packages/gunicorn/workers/base.py", line 130, in load_wsgi
    self.wsgi = self.app.wsgi()
  File "/usr/local/lib/python3.5/site-packages/gunicorn/app/base.py", line 67, in wsgi
    self.callable = self.load()
  File "/usr/local/lib/python3.5/site-packages/gunicorn/app/wsgiapp.py", line 65, in load
    return self.load_wsgiapp()
  File "/usr/local/lib/python3.5/site-packages/gunicorn/app/wsgiapp.py", line 52, in load_wsgiapp
    return util.import_app(self.app_uri)
  File "/usr/local/lib/python3.5/site-packages/gunicorn/util.py", line 357, in import_app
    __import__(module)
ImportError: No module named 'app'
[2016-04-05 18:00:32 +0000] [13] [INFO] Worker exiting (pid: 13)
[2016-04-05 18:00:32 +0000] [14] [INFO] Booting worker with pid: 14
[2016-04-05 18:00:32 +0000] [14] [ERROR] Exception in worker process:
Traceback (most recent call last):
  File "/usr/local/lib/python3.5/site-packages/gunicorn/arbiter.py", line 515, in spawn_worker
    worker.init_process()
  File "/usr/local/lib/python3.5/site-packages/gunicorn/workers/base.py", line 122, in init_process
    self.load_wsgi()
  File "/usr/local/lib/python3.5/site-packages/gunicorn/workers/base.py", line 130, in load_wsgi
    self.wsgi = self.app.wsgi()
  File "/usr/local/lib/python3.5/site-packages/gunicorn/app/base.py", line 67, in wsgi
    self.callable = self.load()
  File "/usr/local/lib/python3.5/site-packages/gunicorn/app/wsgiapp.py", line 65, in load
    return self.load_wsgiapp()
  File "/usr/local/lib/python3.5/site-packages/gunicorn/app/wsgiapp.py", line 52, in load_wsgiapp
    return util.import_app(self.app_uri)
  File "/usr/local/lib/python3.5/site-packages/gunicorn/util.py", line 357, in import_app
    __import__(module)
ImportError: No module named 'app'
Traceback (most recent call last):
  File "/usr/local/lib/python3.5/site-packages/gunicorn/arbiter.py", line 515, in spawn_worker
    worker.init_process()
  File "/usr/local/lib/python3.5/site-packages/gunicorn/workers/base.py", line 122, in init_process
    self.load_wsgi()
  File "/usr/local/lib/python3.5/site-packages/gunicorn/workers/base.py", line 130, in load_wsgi
    self.wsgi = self.app.wsgi()
  File "/usr/local/lib/python3.5/site-packages/gunicorn/app/base.py", line 67, in wsgi
    self.callable = self.load()
  File "/usr/local/lib/python3.5/site-packages/gunicorn/app/wsgiapp.py", line 65, in load
    return self.load_wsgiapp()
  File "/usr/local/lib/python3.5/site-packages/gunicorn/app/wsgiapp.py", line 52, in load_wsgiapp
    return util.import_app(self.app_uri)
  File "/usr/local/lib/python3.5/site-packages/gunicorn/util.py", line 357, in import_app
    __import__(module)
ImportError: No module named 'app'
[2016-04-05 18:00:32 +0000] [14] [INFO] Worker exiting (pid: 14)
[2016-04-05 18:00:32 +0000] [10] [INFO] Shutting down: Master
[2016-04-05 18:00:32 +0000] [10] [INFO] Reason: Worker failed to boot.
[2016-04-05 18:00:35 +0000] [9] [INFO] Starting gunicorn 19.4.5
[2016-04-05 18:00:35 +0000] [9] [INFO] Listening at: http://0.0.0.0:8000 (9)
[2016-04-05 18:00:35 +0000] [9] [INFO] Using worker: sync
[2016-04-05 18:00:35 +0000] [12] [INFO] Booting worker with pid: 12
[2016-04-05 18:00:35 +0000] [12] [ERROR] Exception in worker process:
Traceback (most recent call last):
  File "/usr/local/lib/python3.5/site-packages/gunicorn/arbiter.py", line 515, in spawn_worker
    worker.init_process()
  File "/usr/local/lib/python3.5/site-packages/gunicorn/workers/base.py", line 122, in init_process
    self.load_wsgi()
  File "/usr/local/lib/python3.5/site-packages/gunicorn/workers/base.py", line 130, in load_wsgi
    self.wsgi = self.app.wsgi()
  File "/usr/local/lib/python3.5/site-packages/gunicorn/app/base.py", line 67, in wsgi
    self.callable = self.load()
  File "/usr/local/lib/python3.5/site-packages/gunicorn/app/wsgiapp.py", line 65, in load
    return self.load_wsgiapp()
  File "/usr/local/lib/python3.5/site-packages/gunicorn/app/wsgiapp.py", line 52, in load_wsgiapp
    return util.import_app(self.app_uri)
  File "/usr/local/lib/python3.5/site-packages/gunicorn/util.py", line 357, in import_app
    __import__(module)
ImportError: No module named 'app'
Traceback (most recent call last):
  File "/usr/local/lib/python3.5/site-packages/gunicorn/arbiter.py", line 515, in spawn_worker
    worker.init_process()
  File "/usr/local/lib/python3.5/site-packages/gunicorn/workers/base.py", line 122, in init_process
    self.load_wsgi()
  File "/usr/local/lib/python3.5/site-packages/gunicorn/workers/base.py", line 130, in load_wsgi
    self.wsgi = self.app.wsgi()
  File "/usr/local/lib/python3.5/site-packages/gunicorn/app/base.py", line 67, in wsgi
    self.callable = self.load()
  File "/usr/local/lib/python3.5/site-packages/gunicorn/app/wsgiapp.py", line 65, in load
    return self.load_wsgiapp()
  File "/usr/local/lib/python3.5/site-packages/gunicorn/app/wsgiapp.py", line 52, in load_wsgiapp
    return util.import_app(self.app_uri)
  File "/usr/local/lib/python3.5/site-packages/gunicorn/util.py", line 357, in import_app
    __import__(module)
ImportError: No module named 'app'
[2016-04-05 18:00:35 +0000] [12] [INFO] Worker exiting (pid: 12)
[2016-04-05 18:00:35 +0000] [13] [INFO] Booting worker with pid: 13
[2016-04-05 18:00:35 +0000] [13] [ERROR] Exception in worker process:
Traceback (most recent call last):
  File "/usr/local/lib/python3.5/site-packages/gunicorn/arbiter.py", line 515, in spawn_worker
    worker.init_process()
  File "/usr/local/lib/python3.5/site-packages/gunicorn/workers/base.py", line 122, in init_process
    self.load_wsgi()
  File "/usr/local/lib/python3.5/site-packages/gunicorn/workers/base.py", line 130, in load_wsgi
    self.wsgi = self.app.wsgi()
  File "/usr/local/lib/python3.5/site-packages/gunicorn/app/base.py", line 67, in wsgi
    self.callable = self.load()
  File "/usr/local/lib/python3.5/site-packages/gunicorn/app/wsgiapp.py", line 65, in load
    return self.load_wsgiapp()
  File "/usr/local/lib/python3.5/site-packages/gunicorn/app/wsgiapp.py", line 52, in load_wsgiapp
    return util.import_app(self.app_uri)
  File "/usr/local/lib/python3.5/site-packages/gunicorn/util.py", line 357, in import_app
    __import__(module)
ImportError: No module named 'app'
Traceback (most recent call last):
  File "/usr/local/lib/python3.5/site-packages/gunicorn/arbiter.py", line 515, in spawn_worker
    worker.init_process()
  File "/usr/local/lib/python3.5/site-packages/gunicorn/workers/base.py", line 122, in init_process
    self.load_wsgi()
  File "/usr/local/lib/python3.5/site-packages/gunicorn/workers/base.py", line 130, in load_wsgi
    self.wsgi = self.app.wsgi()
  File "/usr/local/lib/python3.5/site-packages/gunicorn/app/base.py", line 67, in wsgi
    self.callable = self.load()
  File "/usr/local/lib/python3.5/site-packages/gunicorn/app/wsgiapp.py", line 65, in load
    return self.load_wsgiapp()
  File "/usr/local/lib/python3.5/site-packages/gunicorn/app/wsgiapp.py", line 52, in load_wsgiapp
    return util.import_app(self.app_uri)
  File "/usr/local/lib/python3.5/site-packages/gunicorn/util.py", line 357, in import_app
    __import__(module)
ImportError: No module named 'app'
[2016-04-05 18:00:35 +0000] [13] [INFO] Worker exiting (pid: 13)
[2016-04-05 18:00:35 +0000] [9] [INFO] Shutting down: Master
[2016-04-05 18:00:35 +0000] [9] [INFO] Reason: Worker failed to boot.
[2016-04-05 18:00:49 +0000] [9] [INFO] Starting gunicorn 19.4.5
[2016-04-05 18:00:49 +0000] [9] [INFO] Listening at: http://0.0.0.0:8000 (9)
[2016-04-05 18:00:49 +0000] [9] [INFO] Using worker: sync
[2016-04-05 18:00:49 +0000] [12] [INFO] Booting worker with pid: 12
[2016-04-05 18:00:49 +0000] [12] [ERROR] Exception in worker process:
Traceback (most recent call last):
  File "/usr/local/lib/python3.5/site-packages/gunicorn/arbiter.py", line 515, in spawn_worker
    worker.init_process()
  File "/usr/local/lib/python3.5/site-packages/gunicorn/workers/base.py", line 122, in init_process
    self.load_wsgi()
  File "/usr/local/lib/python3.5/site-packages/gunicorn/workers/base.py", line 130, in load_wsgi
    self.wsgi = self.app.wsgi()
  File "/usr/local/lib/python3.5/site-packages/gunicorn/app/base.py", line 67, in wsgi
    self.callable = self.load()
  File "/usr/local/lib/python3.5/site-packages/gunicorn/app/wsgiapp.py", line 65, in load
    return self.load_wsgiapp()
  File "/usr/local/lib/python3.5/site-packages/gunicorn/app/wsgiapp.py", line 52, in load_wsgiapp
    return util.import_app(self.app_uri)
  File "/usr/local/lib/python3.5/site-packages/gunicorn/util.py", line 357, in import_app
    __import__(module)
ImportError: No module named 'app'
Traceback (most recent call last):
  File "/usr/local/lib/python3.5/site-packages/gunicorn/arbiter.py", line 515, in spawn_worker
    worker.init_process()
  File "/usr/local/lib/python3.5/site-packages/gunicorn/workers/base.py", line 122, in init_process
    self.load_wsgi()
  File "/usr/local/lib/python3.5/site-packages/gunicorn/workers/base.py", line 130, in load_wsgi
    self.wsgi = self.app.wsgi()
  File "/usr/local/lib/python3.5/site-packages/gunicorn/app/base.py", line 67, in wsgi
    self.callable = self.load()
  File "/usr/local/lib/python3.5/site-packages/gunicorn/app/wsgiapp.py", line 65, in load
    return self.load_wsgiapp()
  File "/usr/local/lib/python3.5/site-packages/gunicorn/app/wsgiapp.py", line 52, in load_wsgiapp
    return util.import_app(self.app_uri)
  File "/usr/local/lib/python3.5/site-packages/gunicorn/util.py", line 357, in import_app
    __import__(module)
ImportError: No module named 'app'
[2016-04-05 18:00:49 +0000] [12] [INFO] Worker exiting (pid: 12)
[2016-04-05 18:00:49 +0000] [9] [INFO] Shutting down: Master
[2016-04-05 18:00:49 +0000] [9] [INFO] Reason: Worker failed to boot.
[2016-04-05 18:01:27 +0000] [10] [INFO] Starting gunicorn 19.4.5
[2016-04-05 18:01:27 +0000] [10] [INFO] Listening at: http://0.0.0.0:8000 (10)
[2016-04-05 18:01:27 +0000] [10] [INFO] Using worker: sync
[2016-04-05 18:01:27 +0000] [13] [INFO] Booting worker with pid: 13
[2016-04-05 18:01:27 +0000] [13] [ERROR] Exception in worker process:
Traceback (most recent call last):
  File "/usr/local/lib/python3.5/site-packages/gunicorn/arbiter.py", line 515, in spawn_worker
    worker.init_process()
  File "/usr/local/lib/python3.5/site-packages/gunicorn/workers/base.py", line 122, in init_process
    self.load_wsgi()
  File "/usr/local/lib/python3.5/site-packages/gunicorn/workers/base.py", line 130, in load_wsgi
    self.wsgi = self.app.wsgi()
  File "/usr/local/lib/python3.5/site-packages/gunicorn/app/base.py", line 67, in wsgi
    self.callable = self.load()
  File "/usr/local/lib/python3.5/site-packages/gunicorn/app/wsgiapp.py", line 65, in load
    return self.load_wsgiapp()
  File "/usr/local/lib/python3.5/site-packages/gunicorn/app/wsgiapp.py", line 52, in load_wsgiapp
    return util.import_app(self.app_uri)
  File "/usr/local/lib/python3.5/site-packages/gunicorn/util.py", line 357, in import_app
    __import__(module)
ImportError: No module named 'app'
Traceback (most recent call last):
  File "/usr/local/lib/python3.5/site-packages/gunicorn/arbiter.py", line 515, in spawn_worker
    worker.init_process()
  File "/usr/local/lib/python3.5/site-packages/gunicorn/workers/base.py", line 122, in init_process
    self.load_wsgi()
  File "/usr/local/lib/python3.5/site-packages/gunicorn/workers/base.py", line 130, in load_wsgi
    self.wsgi = self.app.wsgi()
  File "/usr/local/lib/python3.5/site-packages/gunicorn/app/base.py", line 67, in wsgi
    self.callable = self.load()
  File "/usr/local/lib/python3.5/site-packages/gunicorn/app/wsgiapp.py", line 65, in load
    return self.load_wsgiapp()
  File "/usr/local/lib/python3.5/site-packages/gunicorn/app/wsgiapp.py", line 52, in load_wsgiapp
    return util.import_app(self.app_uri)
  File "/usr/local/lib/python3.5/site-packages/gunicorn/util.py", line 357, in import_app
    __import__(module)
ImportError: No module named 'app'
[2016-04-05 18:01:27 +0000] [13] [INFO] Worker exiting (pid: 13)
[2016-04-05 18:01:27 +0000] [14] [INFO] Booting worker with pid: 14
[2016-04-05 18:01:27 +0000] [14] [ERROR] Exception in worker process:
Traceback (most recent call last):
  File "/usr/local/lib/python3.5/site-packages/gunicorn/arbiter.py", line 515, in spawn_worker
    worker.init_process()
  File "/usr/local/lib/python3.5/site-packages/gunicorn/workers/base.py", line 122, in init_process
    self.load_wsgi()
  File "/usr/local/lib/python3.5/site-packages/gunicorn/workers/base.py", line 130, in load_wsgi
    self.wsgi = self.app.wsgi()
  File "/usr/local/lib/python3.5/site-packages/gunicorn/app/base.py", line 67, in wsgi
    self.callable = self.load()
  File "/usr/local/lib/python3.5/site-packages/gunicorn/app/wsgiapp.py", line 65, in load
    return self.load_wsgiapp()
  File "/usr/local/lib/python3.5/site-packages/gunicorn/app/wsgiapp.py", line 52, in load_wsgiapp
    return util.import_app(self.app_uri)
  File "/usr/local/lib/python3.5/site-packages/gunicorn/util.py", line 357, in import_app
    __import__(module)
ImportError: No module named 'app'
Traceback (most recent call last):
  File "/usr/local/lib/python3.5/site-packages/gunicorn/arbiter.py", line 515, in spawn_worker
    worker.init_process()
  File "/usr/local/lib/python3.5/site-packages/gunicorn/workers/base.py", line 122, in init_process
    self.load_wsgi()
  File "/usr/local/lib/python3.5/site-packages/gunicorn/workers/base.py", line 130, in load_wsgi
    self.wsgi = self.app.wsgi()
  File "/usr/local/lib/python3.5/site-packages/gunicorn/app/base.py", line 67, in wsgi
    self.callable = self.load()
  File "/usr/local/lib/python3.5/site-packages/gunicorn/app/wsgiapp.py", line 65, in load
    return self.load_wsgiapp()
  File "/usr/local/lib/python3.5/site-packages/gunicorn/app/wsgiapp.py", line 52, in load_wsgiapp
    return util.import_app(self.app_uri)
  File "/usr/local/lib/python3.5/site-packages/gunicorn/util.py", line 357, in import_app
    __import__(module)
ImportError: No module named 'app'
[2016-04-05 18:01:27 +0000] [14] [INFO] Worker exiting (pid: 14)
[2016-04-05 18:01:27 +0000] [10] [INFO] Shutting down: Master
[2016-04-05 18:01:27 +0000] [10] [INFO] Reason: Worker failed to boot.
[2016-04-05 18:01:32 +0000] [15] [INFO] Starting gunicorn 19.4.5
[2016-04-05 18:01:32 +0000] [15] [INFO] Listening at: http://0.0.0.0:8000 (15)
[2016-04-05 18:01:32 +0000] [15] [INFO] Using worker: sync
[2016-04-05 18:01:32 +0000] [18] [INFO] Booting worker with pid: 18
[2016-04-05 18:01:32 +0000] [18] [ERROR] Exception in worker process:
Traceback (most recent call last):
  File "/usr/local/lib/python3.5/site-packages/gunicorn/arbiter.py", line 515, in spawn_worker
    worker.init_process()
  File "/usr/local/lib/python3.5/site-packages/gunicorn/workers/base.py", line 122, in init_process
    self.load_wsgi()
  File "/usr/local/lib/python3.5/site-packages/gunicorn/workers/base.py", line 130, in load_wsgi
    self.wsgi = self.app.wsgi()
  File "/usr/local/lib/python3.5/site-packages/gunicorn/app/base.py", line 67, in wsgi
    self.callable = self.load()
  File "/usr/local/lib/python3.5/site-packages/gunicorn/app/wsgiapp.py", line 65, in load
    return self.load_wsgiapp()
  File "/usr/local/lib/python3.5/site-packages/gunicorn/app/wsgiapp.py", line 52, in load_wsgiapp
    return util.import_app(self.app_uri)
  File "/usr/local/lib/python3.5/site-packages/gunicorn/util.py", line 357, in import_app
    __import__(module)
ImportError: No module named 'ap'
Traceback (most recent call last):
  File "/usr/local/lib/python3.5/site-packages/gunicorn/arbiter.py", line 515, in spawn_worker
    worker.init_process()
  File "/usr/local/lib/python3.5/site-packages/gunicorn/workers/base.py", line 122, in init_process
    self.load_wsgi()
  File "/usr/local/lib/python3.5/site-packages/gunicorn/workers/base.py", line 130, in load_wsgi
    self.wsgi = self.app.wsgi()
  File "/usr/local/lib/python3.5/site-packages/gunicorn/app/base.py", line 67, in wsgi
    self.callable = self.load()
  File "/usr/local/lib/python3.5/site-packages/gunicorn/app/wsgiapp.py", line 65, in load
    return self.load_wsgiapp()
  File "/usr/local/lib/python3.5/site-packages/gunicorn/app/wsgiapp.py", line 52, in load_wsgiapp
    return util.import_app(self.app_uri)
  File "/usr/local/lib/python3.5/site-packages/gunicorn/util.py", line 357, in import_app
    __import__(module)
ImportError: No module named 'ap'
[2016-04-05 18:01:32 +0000] [18] [INFO] Worker exiting (pid: 18)
[2016-04-05 18:01:32 +0000] [15] [INFO] Shutting down: Master
[2016-04-05 18:01:32 +0000] [15] [INFO] Reason: Worker failed to boot.
[2016-04-05 18:01:35 +0000] [19] [INFO] Starting gunicorn 19.4.5
[2016-04-05 18:01:35 +0000] [19] [INFO] Listening at: http://0.0.0.0:8000 (19)
[2016-04-05 18:01:35 +0000] [19] [INFO] Using worker: sync
[2016-04-05 18:01:35 +0000] [22] [INFO] Booting worker with pid: 22
[2016-04-05 18:01:35 +0000] [22] [ERROR] Exception in worker process:
Traceback (most recent call last):
  File "/usr/local/lib/python3.5/site-packages/gunicorn/arbiter.py", line 515, in spawn_worker
    worker.init_process()
  File "/usr/local/lib/python3.5/site-packages/gunicorn/workers/base.py", line 122, in init_process
    self.load_wsgi()
  File "/usr/local/lib/python3.5/site-packages/gunicorn/workers/base.py", line 130, in load_wsgi
    self.wsgi = self.app.wsgi()
  File "/usr/local/lib/python3.5/site-packages/gunicorn/app/base.py", line 67, in wsgi
    self.callable = self.load()
  File "/usr/local/lib/python3.5/site-packages/gunicorn/app/wsgiapp.py", line 65, in load
    return self.load_wsgiapp()
  File "/usr/local/lib/python3.5/site-packages/gunicorn/app/wsgiapp.py", line 52, in load_wsgiapp
    return util.import_app(self.app_uri)
  File "/usr/local/lib/python3.5/site-packages/gunicorn/util.py", line 357, in import_app
    __import__(module)
ImportError: No module named 'ap'
Traceback (most recent call last):
  File "/usr/local/lib/python3.5/site-packages/gunicorn/arbiter.py", line 515, in spawn_worker
    worker.init_process()
  File "/usr/local/lib/python3.5/site-packages/gunicorn/workers/base.py", line 122, in init_process
    self.load_wsgi()
  File "/usr/local/lib/python3.5/site-packages/gunicorn/workers/base.py", line 130, in load_wsgi
    self.wsgi = self.app.wsgi()
  File "/usr/local/lib/python3.5/site-packages/gunicorn/app/base.py", line 67, in wsgi
    self.callable = self.load()
  File "/usr/local/lib/python3.5/site-packages/gunicorn/app/wsgiapp.py", line 65, in load
    return self.load_wsgiapp()
  File "/usr/local/lib/python3.5/site-packages/gunicorn/app/wsgiapp.py", line 52, in load_wsgiapp
    return util.import_app(self.app_uri)
  File "/usr/local/lib/python3.5/site-packages/gunicorn/util.py", line 357, in import_app
    __import__(module)
ImportError: No module named 'ap'
[2016-04-05 18:01:35 +0000] [22] [INFO] Worker exiting (pid: 22)
[2016-04-05 18:01:35 +0000] [19] [INFO] Shutting down: Master
[2016-04-05 18:01:35 +0000] [19] [INFO] Reason: Worker failed to boot.
[2016-04-05 18:01:49 +0000] [24] [INFO] Starting gunicorn 19.4.5
[2016-04-05 18:01:49 +0000] [24] [INFO] Listening at: http://0.0.0.0:8000 (24)
[2016-04-05 18:01:49 +0000] [24] [INFO] Using worker: sync
[2016-04-05 18:01:49 +0000] [27] [INFO] Booting worker with pid: 27
[2016-04-05 18:01:49 +0000] [29] [INFO] Booting worker with pid: 29
[2016-04-05 18:01:49 +0000] [30] [INFO] Booting worker with pid: 30
[2016-04-05 18:01:49 +0000] [27] [ERROR] Exception in worker process:
Traceback (most recent call last):
  File "/usr/local/lib/python3.5/site-packages/gunicorn/arbiter.py", line 515, in spawn_worker
    worker.init_process()
  File "/usr/local/lib/python3.5/site-packages/gunicorn/workers/base.py", line 122, in init_process
    self.load_wsgi()
  File "/usr/local/lib/python3.5/site-packages/gunicorn/workers/base.py", line 130, in load_wsgi
    self.wsgi = self.app.wsgi()
  File "/usr/local/lib/python3.5/site-packages/gunicorn/app/base.py", line 67, in wsgi
    self.callable = self.load()
  File "/usr/local/lib/python3.5/site-packages/gunicorn/app/wsgiapp.py", line 65, in load
    return self.load_wsgiapp()
  File "/usr/local/lib/python3.5/site-packages/gunicorn/app/wsgiapp.py", line 52, in load_wsgiapp
    return util.import_app(self.app_uri)
  File "/usr/local/lib/python3.5/site-packages/gunicorn/util.py", line 357, in import_app
    __import__(module)
  File "/app/app_wsgi.py", line 16, in <module>
    application = get_wsgi_application()
  File "/usr/local/lib/python3.5/site-packages/django/core/wsgi.py", line 13, in get_wsgi_application
    django.setup()
  File "/usr/local/lib/python3.5/site-packages/django/__init__.py", line 17, in setup
    configure_logging(settings.LOGGING_CONFIG, settings.LOGGING)
  File "/usr/local/lib/python3.5/site-packages/django/conf/__init__.py", line 55, in __getattr__
    self._setup(name)
  File "/usr/local/lib/python3.5/site-packages/django/conf/__init__.py", line 43, in _setup
    self._wrapped = Settings(settings_module)
  File "/usr/local/lib/python3.5/site-packages/django/conf/__init__.py", line 99, in __init__
    mod = importlib.import_module(self.SETTINGS_MODULE)
  File "/usr/local/lib/python3.5/importlib/__init__.py", line 126, in import_module
    return _bootstrap._gcd_import(name[level:], package, level)
ImportError: No module named 'conf'
Traceback (most recent call last):
  File "/usr/local/lib/python3.5/site-packages/gunicorn/arbiter.py", line 515, in spawn_worker
    worker.init_process()
  File "/usr/local/lib/python3.5/site-packages/gunicorn/workers/base.py", line 122, in init_process
    self.load_wsgi()
  File "/usr/local/lib/python3.5/site-packages/gunicorn/workers/base.py", line 130, in load_wsgi
    self.wsgi = self.app.wsgi()
  File "/usr/local/lib/python3.5/site-packages/gunicorn/app/base.py", line 67, in wsgi
    self.callable = self.load()
  File "/usr/local/lib/python3.5/site-packages/gunicorn/app/wsgiapp.py", line 65, in load
    return self.load_wsgiapp()
  File "/usr/local/lib/python3.5/site-packages/gunicorn/app/wsgiapp.py", line 52, in load_wsgiapp
    return util.import_app(self.app_uri)
  File "/usr/local/lib/python3.5/site-packages/gunicorn/util.py", line 357, in import_app
    __import__(module)
  File "/app/app_wsgi.py", line 16, in <module>
    application = get_wsgi_application()
  File "/usr/local/lib/python3.5/site-packages/django/core/wsgi.py", line 13, in get_wsgi_application
    django.setup()
  File "/usr/local/lib/python3.5/site-packages/django/__init__.py", line 17, in setup
    configure_logging(settings.LOGGING_CONFIG, settings.LOGGING)
  File "/usr/local/lib/python3.5/site-packages/django/conf/__init__.py", line 55, in __getattr__
    self._setup(name)
  File "/usr/local/lib/python3.5/site-packages/django/conf/__init__.py", line 43, in _setup
    self._wrapped = Settings(settings_module)
  File "/usr/local/lib/python3.5/site-packages/django/conf/__init__.py", line 99, in __init__
    mod = importlib.import_module(self.SETTINGS_MODULE)
  File "/usr/local/lib/python3.5/importlib/__init__.py", line 126, in import_module
    return _bootstrap._gcd_import(name[level:], package, level)
ImportError: No module named 'conf'
[2016-04-05 18:01:49 +0000] [27] [INFO] Worker exiting (pid: 27)
[2016-04-05 18:01:49 +0000] [33] [INFO] Booting worker with pid: 33
[2016-04-05 18:01:49 +0000] [29] [ERROR] Exception in worker process:
Traceback (most recent call last):
  File "/usr/local/lib/python3.5/site-packages/gunicorn/arbiter.py", line 515, in spawn_worker
    worker.init_process()
  File "/usr/local/lib/python3.5/site-packages/gunicorn/workers/base.py", line 122, in init_process
    self.load_wsgi()
  File "/usr/local/lib/python3.5/site-packages/gunicorn/workers/base.py", line 130, in load_wsgi
    self.wsgi = self.app.wsgi()
  File "/usr/local/lib/python3.5/site-packages/gunicorn/app/base.py", line 67, in wsgi
    self.callable = self.load()
  File "/usr/local/lib/python3.5/site-packages/gunicorn/app/wsgiapp.py", line 65, in load
    return self.load_wsgiapp()
  File "/usr/local/lib/python3.5/site-packages/gunicorn/app/wsgiapp.py", line 52, in load_wsgiapp
    return util.import_app(self.app_uri)
  File "/usr/local/lib/python3.5/site-packages/gunicorn/util.py", line 357, in import_app
    __import__(module)
  File "/app/app_wsgi.py", line 16, in <module>
    application = get_wsgi_application()
  File "/usr/local/lib/python3.5/site-packages/django/core/wsgi.py", line 13, in get_wsgi_application
    django.setup()
  File "/usr/local/lib/python3.5/site-packages/django/__init__.py", line 17, in setup
    configure_logging(settings.LOGGING_CONFIG, settings.LOGGING)
  File "/usr/local/lib/python3.5/site-packages/django/conf/__init__.py", line 55, in __getattr__
    self._setup(name)
  File "/usr/local/lib/python3.5/site-packages/django/conf/__init__.py", line 43, in _setup
    self._wrapped = Settings(settings_module)
  File "/usr/local/lib/python3.5/site-packages/django/conf/__init__.py", line 99, in __init__
    mod = importlib.import_module(self.SETTINGS_MODULE)
  File "/usr/local/lib/python3.5/importlib/__init__.py", line 126, in import_module
    return _bootstrap._gcd_import(name[level:], package, level)
ImportError: No module named 'conf'
Traceback (most recent call last):
  File "/usr/local/lib/python3.5/site-packages/gunicorn/arbiter.py", line 515, in spawn_worker
    worker.init_process()
  File "/usr/local/lib/python3.5/site-packages/gunicorn/workers/base.py", line 122, in init_process
    self.load_wsgi()
  File "/usr/local/lib/python3.5/site-packages/gunicorn/workers/base.py", line 130, in load_wsgi
    self.wsgi = self.app.wsgi()
  File "/usr/local/lib/python3.5/site-packages/gunicorn/app/base.py", line 67, in wsgi
    self.callable = self.load()
  File "/usr/local/lib/python3.5/site-packages/gunicorn/app/wsgiapp.py", line 65, in load
    return self.load_wsgiapp()
  File "/usr/local/lib/python3.5/site-packages/gunicorn/app/wsgiapp.py", line 52, in load_wsgiapp
    return util.import_app(self.app_uri)
  File "/usr/local/lib/python3.5/site-packages/gunicorn/util.py", line 357, in import_app
    __import__(module)
  File "/app/app_wsgi.py", line 16, in <module>
    application = get_wsgi_application()
  File "/usr/local/lib/python3.5/site-packages/django/core/wsgi.py", line 13, in get_wsgi_application
    django.setup()
  File "/usr/local/lib/python3.5/site-packages/django/__init__.py", line 17, in setup
    configure_logging(settings.LOGGING_CONFIG, settings.LOGGING)
  File "/usr/local/lib/python3.5/site-packages/django/conf/__init__.py", line 55, in __getattr__
    self._setup(name)
  File "/usr/local/lib/python3.5/site-packages/django/conf/__init__.py", line 43, in _setup
    self._wrapped = Settings(settings_module)
  File "/usr/local/lib/python3.5/site-packages/django/conf/__init__.py", line 99, in __init__
    mod = importlib.import_module(self.SETTINGS_MODULE)
  File "/usr/local/lib/python3.5/importlib/__init__.py", line 126, in import_module
    return _bootstrap._gcd_import(name[level:], package, level)
ImportError: No module named 'conf'
[2016-04-05 18:01:49 +0000] [29] [INFO] Worker exiting (pid: 29)
[2016-04-05 18:01:49 +0000] [30] [ERROR] Exception in worker process:
Traceback (most recent call last):
  File "/usr/local/lib/python3.5/site-packages/gunicorn/arbiter.py", line 515, in spawn_worker
    worker.init_process()
  File "/usr/local/lib/python3.5/site-packages/gunicorn/workers/base.py", line 122, in init_process
    self.load_wsgi()
  File "/usr/local/lib/python3.5/site-packages/gunicorn/workers/base.py", line 130, in load_wsgi
    self.wsgi = self.app.wsgi()
  File "/usr/local/lib/python3.5/site-packages/gunicorn/app/base.py", line 67, in wsgi
    self.callable = self.load()
  File "/usr/local/lib/python3.5/site-packages/gunicorn/app/wsgiapp.py", line 65, in load
    return self.load_wsgiapp()
  File "/usr/local/lib/python3.5/site-packages/gunicorn/app/wsgiapp.py", line 52, in load_wsgiapp
    return util.import_app(self.app_uri)
  File "/usr/local/lib/python3.5/site-packages/gunicorn/util.py", line 357, in import_app
    __import__(module)
  File "/app/app_wsgi.py", line 16, in <module>
    application = get_wsgi_application()
  File "/usr/local/lib/python3.5/site-packages/django/core/wsgi.py", line 13, in get_wsgi_application
    django.setup()
  File "/usr/local/lib/python3.5/site-packages/django/__init__.py", line 17, in setup
    configure_logging(settings.LOGGING_CONFIG, settings.LOGGING)
  File "/usr/local/lib/python3.5/site-packages/django/conf/__init__.py", line 55, in __getattr__
    self._setup(name)
  File "/usr/local/lib/python3.5/site-packages/django/conf/__init__.py", line 43, in _setup
    self._wrapped = Settings(settings_module)
  File "/usr/local/lib/python3.5/site-packages/django/conf/__init__.py", line 99, in __init__
    mod = importlib.import_module(self.SETTINGS_MODULE)
  File "/usr/local/lib/python3.5/importlib/__init__.py", line 126, in import_module
    return _bootstrap._gcd_import(name[level:], package, level)
ImportError: No module named 'conf'
Traceback (most recent call last):
  File "/usr/local/lib/python3.5/site-packages/gunicorn/arbiter.py", line 515, in spawn_worker
    worker.init_process()
  File "/usr/local/lib/python3.5/site-packages/gunicorn/workers/base.py", line 122, in init_process
    self.load_wsgi()
  File "/usr/local/lib/python3.5/site-packages/gunicorn/workers/base.py", line 130, in load_wsgi
    self.wsgi = self.app.wsgi()
  File "/usr/local/lib/python3.5/site-packages/gunicorn/app/base.py", line 67, in wsgi
    self.callable = self.load()
  File "/usr/local/lib/python3.5/site-packages/gunicorn/app/wsgiapp.py", line 65, in load
    return self.load_wsgiapp()
  File "/usr/local/lib/python3.5/site-packages/gunicorn/app/wsgiapp.py", line 52, in load_wsgiapp
    return util.import_app(self.app_uri)
  File "/usr/local/lib/python3.5/site-packages/gunicorn/util.py", line 357, in import_app
    __import__(module)
  File "/app/app_wsgi.py", line 16, in <module>
    application = get_wsgi_application()
  File "/usr/local/lib/python3.5/site-packages/django/core/wsgi.py", line 13, in get_wsgi_application
    django.setup()
  File "/usr/local/lib/python3.5/site-packages/django/__init__.py", line 17, in setup
    configure_logging(settings.LOGGING_CONFIG, settings.LOGGING)
  File "/usr/local/lib/python3.5/site-packages/django/conf/__init__.py", line 55, in __getattr__
    self._setup(name)
  File "/usr/local/lib/python3.5/site-packages/django/conf/__init__.py", line 43, in _setup
    self._wrapped = Settings(settings_module)
  File "/usr/local/lib/python3.5/site-packages/django/conf/__init__.py", line 99, in __init__
    mod = importlib.import_module(self.SETTINGS_MODULE)
  File "/usr/local/lib/python3.5/importlib/__init__.py", line 126, in import_module
    return _bootstrap._gcd_import(name[level:], package, level)
ImportError: No module named 'conf'
[2016-04-05 18:01:49 +0000] [30] [INFO] Worker exiting (pid: 30)
[2016-04-05 18:01:49 +0000] [33] [ERROR] Exception in worker process:
Traceback (most recent call last):
  File "/usr/local/lib/python3.5/site-packages/gunicorn/arbiter.py", line 515, in spawn_worker
    worker.init_process()
  File "/usr/local/lib/python3.5/site-packages/gunicorn/workers/base.py", line 122, in init_process
    self.load_wsgi()
  File "/usr/local/lib/python3.5/site-packages/gunicorn/workers/base.py", line 130, in load_wsgi
    self.wsgi = self.app.wsgi()
  File "/usr/local/lib/python3.5/site-packages/gunicorn/app/base.py", line 67, in wsgi
    self.callable = self.load()
  File "/usr/local/lib/python3.5/site-packages/gunicorn/app/wsgiapp.py", line 65, in load
    return self.load_wsgiapp()
  File "/usr/local/lib/python3.5/site-packages/gunicorn/app/wsgiapp.py", line 52, in load_wsgiapp
    return util.import_app(self.app_uri)
  File "/usr/local/lib/python3.5/site-packages/gunicorn/util.py", line 357, in import_app
    __import__(module)
  File "/app/app_wsgi.py", line 16, in <module>
    application = get_wsgi_application()
  File "/usr/local/lib/python3.5/site-packages/django/core/wsgi.py", line 13, in get_wsgi_application
    django.setup()
  File "/usr/local/lib/python3.5/site-packages/django/__init__.py", line 17, in setup
    configure_logging(settings.LOGGING_CONFIG, settings.LOGGING)
  File "/usr/local/lib/python3.5/site-packages/django/conf/__init__.py", line 55, in __getattr__
    self._setup(name)
  File "/usr/local/lib/python3.5/site-packages/django/conf/__init__.py", line 43, in _setup
    self._wrapped = Settings(settings_module)
  File "/usr/local/lib/python3.5/site-packages/django/conf/__init__.py", line 99, in __init__
    mod = importlib.import_module(self.SETTINGS_MODULE)
  File "/usr/local/lib/python3.5/importlib/__init__.py", line 126, in import_module
    return _bootstrap._gcd_import(name[level:], package, level)
ImportError: No module named 'conf'
Traceback (most recent call last):
  File "/usr/local/lib/python3.5/site-packages/gunicorn/arbiter.py", line 515, in spawn_worker
    worker.init_process()
  File "/usr/local/lib/python3.5/site-packages/gunicorn/workers/base.py", line 122, in init_process
    self.load_wsgi()
  File "/usr/local/lib/python3.5/site-packages/gunicorn/workers/base.py", line 130, in load_wsgi
    self.wsgi = self.app.wsgi()
  File "/usr/local/lib/python3.5/site-packages/gunicorn/app/base.py", line 67, in wsgi
    self.callable = self.load()
  File "/usr/local/lib/python3.5/site-packages/gunicorn/app/wsgiapp.py", line 65, in load
    return self.load_wsgiapp()
  File "/usr/local/lib/python3.5/site-packages/gunicorn/app/wsgiapp.py", line 52, in load_wsgiapp
    return util.import_app(self.app_uri)
  File "/usr/local/lib/python3.5/site-packages/gunicorn/util.py", line 357, in import_app
    __import__(module)
  File "/app/app_wsgi.py", line 16, in <module>
    application = get_wsgi_application()
  File "/usr/local/lib/python3.5/site-packages/django/core/wsgi.py", line 13, in get_wsgi_application
    django.setup()
  File "/usr/local/lib/python3.5/site-packages/django/__init__.py", line 17, in setup
    configure_logging(settings.LOGGING_CONFIG, settings.LOGGING)
  File "/usr/local/lib/python3.5/site-packages/django/conf/__init__.py", line 55, in __getattr__
    self._setup(name)
  File "/usr/local/lib/python3.5/site-packages/django/conf/__init__.py", line 43, in _setup
    self._wrapped = Settings(settings_module)
  File "/usr/local/lib/python3.5/site-packages/django/conf/__init__.py", line 99, in __init__
    mod = importlib.import_module(self.SETTINGS_MODULE)
  File "/usr/local/lib/python3.5/importlib/__init__.py", line 126, in import_module
    return _bootstrap._gcd_import(name[level:], package, level)
ImportError: No module named 'conf'
[2016-04-05 18:01:49 +0000] [33] [INFO] Worker exiting (pid: 33)
[2016-04-05 18:01:52 +0000] [35] [INFO] Starting gunicorn 19.4.5
[2016-04-05 18:01:52 +0000] [35] [INFO] Listening at: http://0.0.0.0:8000 (35)
[2016-04-05 18:01:52 +0000] [35] [INFO] Using worker: sync
[2016-04-05 18:01:52 +0000] [38] [INFO] Booting worker with pid: 38
[2016-04-05 18:01:52 +0000] [40] [INFO] Booting worker with pid: 40
[2016-04-05 18:01:52 +0000] [42] [INFO] Booting worker with pid: 42
[2016-04-05 18:01:52 +0000] [43] [INFO] Booting worker with pid: 43
[2016-04-05 18:01:52 +0000] [38] [ERROR] Exception in worker process:
Traceback (most recent call last):
  File "/usr/local/lib/python3.5/site-packages/gunicorn/arbiter.py", line 515, in spawn_worker
    worker.init_process()
  File "/usr/local/lib/python3.5/site-packages/gunicorn/workers/base.py", line 122, in init_process
    self.load_wsgi()
  File "/usr/local/lib/python3.5/site-packages/gunicorn/workers/base.py", line 130, in load_wsgi
    self.wsgi = self.app.wsgi()
  File "/usr/local/lib/python3.5/site-packages/gunicorn/app/base.py", line 67, in wsgi
    self.callable = self.load()
  File "/usr/local/lib/python3.5/site-packages/gunicorn/app/wsgiapp.py", line 65, in load
    return self.load_wsgiapp()
  File "/usr/local/lib/python3.5/site-packages/gunicorn/app/wsgiapp.py", line 52, in load_wsgiapp
    return util.import_app(self.app_uri)
  File "/usr/local/lib/python3.5/site-packages/gunicorn/util.py", line 357, in import_app
    __import__(module)
  File "/app/app_wsgi.py", line 16, in <module>
    application = get_wsgi_application()
  File "/usr/local/lib/python3.5/site-packages/django/core/wsgi.py", line 13, in get_wsgi_application
    django.setup()
  File "/usr/local/lib/python3.5/site-packages/django/__init__.py", line 17, in setup
    configure_logging(settings.LOGGING_CONFIG, settings.LOGGING)
  File "/usr/local/lib/python3.5/site-packages/django/conf/__init__.py", line 55, in __getattr__
    self._setup(name)
  File "/usr/local/lib/python3.5/site-packages/django/conf/__init__.py", line 43, in _setup
    self._wrapped = Settings(settings_module)
  File "/usr/local/lib/python3.5/site-packages/django/conf/__init__.py", line 99, in __init__
    mod = importlib.import_module(self.SETTINGS_MODULE)
  File "/usr/local/lib/python3.5/importlib/__init__.py", line 126, in import_module
    return _bootstrap._gcd_import(name[level:], package, level)
ImportError: No module named 'conf'
Traceback (most recent call last):
  File "/usr/local/lib/python3.5/site-packages/gunicorn/arbiter.py", line 515, in spawn_worker
    worker.init_process()
  File "/usr/local/lib/python3.5/site-packages/gunicorn/workers/base.py", line 122, in init_process
    self.load_wsgi()
  File "/usr/local/lib/python3.5/site-packages/gunicorn/workers/base.py", line 130, in load_wsgi
    self.wsgi = self.app.wsgi()
  File "/usr/local/lib/python3.5/site-packages/gunicorn/app/base.py", line 67, in wsgi
    self.callable = self.load()
  File "/usr/local/lib/python3.5/site-packages/gunicorn/app/wsgiapp.py", line 65, in load
    return self.load_wsgiapp()
  File "/usr/local/lib/python3.5/site-packages/gunicorn/app/wsgiapp.py", line 52, in load_wsgiapp
    return util.import_app(self.app_uri)
  File "/usr/local/lib/python3.5/site-packages/gunicorn/util.py", line 357, in import_app
    __import__(module)
  File "/app/app_wsgi.py", line 16, in <module>
    application = get_wsgi_application()
  File "/usr/local/lib/python3.5/site-packages/django/core/wsgi.py", line 13, in get_wsgi_application
    django.setup()
  File "/usr/local/lib/python3.5/site-packages/django/__init__.py", line 17, in setup
    configure_logging(settings.LOGGING_CONFIG, settings.LOGGING)
  File "/usr/local/lib/python3.5/site-packages/django/conf/__init__.py", line 55, in __getattr__
    self._setup(name)
  File "/usr/local/lib/python3.5/site-packages/django/conf/__init__.py", line 43, in _setup
    self._wrapped = Settings(settings_module)
  File "/usr/local/lib/python3.5/site-packages/django/conf/__init__.py", line 99, in __init__
    mod = importlib.import_module(self.SETTINGS_MODULE)
  File "/usr/local/lib/python3.5/importlib/__init__.py", line 126, in import_module
    return _bootstrap._gcd_import(name[level:], package, level)
ImportError: No module named 'conf'
[2016-04-05 18:01:52 +0000] [38] [INFO] Worker exiting (pid: 38)
[2016-04-05 18:01:52 +0000] [46] [INFO] Booting worker with pid: 46
[2016-04-05 18:01:52 +0000] [40] [ERROR] Exception in worker process:
Traceback (most recent call last):
  File "/usr/local/lib/python3.5/site-packages/gunicorn/arbiter.py", line 515, in spawn_worker
    worker.init_process()
  File "/usr/local/lib/python3.5/site-packages/gunicorn/workers/base.py", line 122, in init_process
    self.load_wsgi()
  File "/usr/local/lib/python3.5/site-packages/gunicorn/workers/base.py", line 130, in load_wsgi
    self.wsgi = self.app.wsgi()
  File "/usr/local/lib/python3.5/site-packages/gunicorn/app/base.py", line 67, in wsgi
    self.callable = self.load()
  File "/usr/local/lib/python3.5/site-packages/gunicorn/app/wsgiapp.py", line 65, in load
    return self.load_wsgiapp()
  File "/usr/local/lib/python3.5/site-packages/gunicorn/app/wsgiapp.py", line 52, in load_wsgiapp
    return util.import_app(self.app_uri)
  File "/usr/local/lib/python3.5/site-packages/gunicorn/util.py", line 357, in import_app
    __import__(module)
  File "/app/app_wsgi.py", line 16, in <module>
    application = get_wsgi_application()
  File "/usr/local/lib/python3.5/site-packages/django/core/wsgi.py", line 13, in get_wsgi_application
    django.setup()
  File "/usr/local/lib/python3.5/site-packages/django/__init__.py", line 17, in setup
    configure_logging(settings.LOGGING_CONFIG, settings.LOGGING)
  File "/usr/local/lib/python3.5/site-packages/django/conf/__init__.py", line 55, in __getattr__
    self._setup(name)
  File "/usr/local/lib/python3.5/site-packages/django/conf/__init__.py", line 43, in _setup
    self._wrapped = Settings(settings_module)
  File "/usr/local/lib/python3.5/site-packages/django/conf/__init__.py", line 99, in __init__
    mod = importlib.import_module(self.SETTINGS_MODULE)
  File "/usr/local/lib/python3.5/importlib/__init__.py", line 126, in import_module
    return _bootstrap._gcd_import(name[level:], package, level)
ImportError: No module named 'conf'
Traceback (most recent call last):
  File "/usr/local/lib/python3.5/site-packages/gunicorn/arbiter.py", line 515, in spawn_worker
    worker.init_process()
  File "/usr/local/lib/python3.5/site-packages/gunicorn/workers/base.py", line 122, in init_process
    self.load_wsgi()
  File "/usr/local/lib/python3.5/site-packages/gunicorn/workers/base.py", line 130, in load_wsgi
    self.wsgi = self.app.wsgi()
  File "/usr/local/lib/python3.5/site-packages/gunicorn/app/base.py", line 67, in wsgi
    self.callable = self.load()
  File "/usr/local/lib/python3.5/site-packages/gunicorn/app/wsgiapp.py", line 65, in load
    return self.load_wsgiapp()
  File "/usr/local/lib/python3.5/site-packages/gunicorn/app/wsgiapp.py", line 52, in load_wsgiapp
    return util.import_app(self.app_uri)
  File "/usr/local/lib/python3.5/site-packages/gunicorn/util.py", line 357, in import_app
    __import__(module)
  File "/app/app_wsgi.py", line 16, in <module>
    application = get_wsgi_application()
  File "/usr/local/lib/python3.5/site-packages/django/core/wsgi.py", line 13, in get_wsgi_application
    django.setup()
  File "/usr/local/lib/python3.5/site-packages/django/__init__.py", line 17, in setup
    configure_logging(settings.LOGGING_CONFIG, settings.LOGGING)
  File "/usr/local/lib/python3.5/site-packages/django/conf/__init__.py", line 55, in __getattr__
    self._setup(name)
  File "/usr/local/lib/python3.5/site-packages/django/conf/__init__.py", line 43, in _setup
    self._wrapped = Settings(settings_module)
  File "/usr/local/lib/python3.5/site-packages/django/conf/__init__.py", line 99, in __init__
    mod = importlib.import_module(self.SETTINGS_MODULE)
  File "/usr/local/lib/python3.5/importlib/__init__.py", line 126, in import_module
    return _bootstrap._gcd_import(name[level:], package, level)
ImportError: No module named 'conf'
[2016-04-05 18:01:52 +0000] [40] [INFO] Worker exiting (pid: 40)
[2016-04-05 18:01:52 +0000] [43] [ERROR] Exception in worker process:
Traceback (most recent call last):
  File "/usr/local/lib/python3.5/site-packages/gunicorn/arbiter.py", line 515, in spawn_worker
    worker.init_process()
  File "/usr/local/lib/python3.5/site-packages/gunicorn/workers/base.py", line 122, in init_process
    self.load_wsgi()
  File "/usr/local/lib/python3.5/site-packages/gunicorn/workers/base.py", line 130, in load_wsgi
    self.wsgi = self.app.wsgi()
  File "/usr/local/lib/python3.5/site-packages/gunicorn/app/base.py", line 67, in wsgi
    self.callable = self.load()
  File "/usr/local/lib/python3.5/site-packages/gunicorn/app/wsgiapp.py", line 65, in load
    return self.load_wsgiapp()
  File "/usr/local/lib/python3.5/site-packages/gunicorn/app/wsgiapp.py", line 52, in load_wsgiapp
    return util.import_app(self.app_uri)
  File "/usr/local/lib/python3.5/site-packages/gunicorn/util.py", line 357, in import_app
    __import__(module)
  File "/app/app_wsgi.py", line 16, in <module>
    application = get_wsgi_application()
  File "/usr/local/lib/python3.5/site-packages/django/core/wsgi.py", line 13, in get_wsgi_application
    django.setup()
  File "/usr/local/lib/python3.5/site-packages/django/__init__.py", line 17, in setup
    configure_logging(settings.LOGGING_CONFIG, settings.LOGGING)
  File "/usr/local/lib/python3.5/site-packages/django/conf/__init__.py", line 55, in __getattr__
    self._setup(name)
  File "/usr/local/lib/python3.5/site-packages/django/conf/__init__.py", line 43, in _setup
    self._wrapped = Settings(settings_module)
  File "/usr/local/lib/python3.5/site-packages/django/conf/__init__.py", line 99, in __init__
    mod = importlib.import_module(self.SETTINGS_MODULE)
  File "/usr/local/lib/python3.5/importlib/__init__.py", line 126, in import_module
    return _bootstrap._gcd_import(name[level:], package, level)
ImportError: No module named 'conf'
Traceback (most recent call last):
  File "/usr/local/lib/python3.5/site-packages/gunicorn/arbiter.py", line 515, in spawn_worker
    worker.init_process()
  File "/usr/local/lib/python3.5/site-packages/gunicorn/workers/base.py", line 122, in init_process
    self.load_wsgi()
  File "/usr/local/lib/python3.5/site-packages/gunicorn/workers/base.py", line 130, in load_wsgi
    self.wsgi = self.app.wsgi()
  File "/usr/local/lib/python3.5/site-packages/gunicorn/app/base.py", line 67, in wsgi
    self.callable = self.load()
  File "/usr/local/lib/python3.5/site-packages/gunicorn/app/wsgiapp.py", line 65, in load
    return self.load_wsgiapp()
  File "/usr/local/lib/python3.5/site-packages/gunicorn/app/wsgiapp.py", line 52, in load_wsgiapp
    return util.import_app(self.app_uri)
  File "/usr/local/lib/python3.5/site-packages/gunicorn/util.py", line 357, in import_app
    __import__(module)
  File "/app/app_wsgi.py", line 16, in <module>
    application = get_wsgi_application()
  File "/usr/local/lib/python3.5/site-packages/django/core/wsgi.py", line 13, in get_wsgi_application
    django.setup()
  File "/usr/local/lib/python3.5/site-packages/django/__init__.py", line 17, in setup
    configure_logging(settings.LOGGING_CONFIG, settings.LOGGING)
  File "/usr/local/lib/python3.5/site-packages/django/conf/__init__.py", line 55, in __getattr__
    self._setup(name)
  File "/usr/local/lib/python3.5/site-packages/django/conf/__init__.py", line 43, in _setup
    self._wrapped = Settings(settings_module)
  File "/usr/local/lib/python3.5/site-packages/django/conf/__init__.py", line 99, in __init__
    mod = importlib.import_module(self.SETTINGS_MODULE)
  File "/usr/local/lib/python3.5/importlib/__init__.py", line 126, in import_module
    return _bootstrap._gcd_import(name[level:], package, level)
ImportError: No module named 'conf'
[2016-04-05 18:01:52 +0000] [43] [INFO] Worker exiting (pid: 43)
[2016-04-05 18:01:52 +0000] [42] [ERROR] Exception in worker process:
Traceback (most recent call last):
  File "/usr/local/lib/python3.5/site-packages/gunicorn/arbiter.py", line 515, in spawn_worker
    worker.init_process()
  File "/usr/local/lib/python3.5/site-packages/gunicorn/workers/base.py", line 122, in init_process
    self.load_wsgi()
  File "/usr/local/lib/python3.5/site-packages/gunicorn/workers/base.py", line 130, in load_wsgi
    self.wsgi = self.app.wsgi()
  File "/usr/local/lib/python3.5/site-packages/gunicorn/app/base.py", line 67, in wsgi
    self.callable = self.load()
  File "/usr/local/lib/python3.5/site-packages/gunicorn/app/wsgiapp.py", line 65, in load
    return self.load_wsgiapp()
  File "/usr/local/lib/python3.5/site-packages/gunicorn/app/wsgiapp.py", line 52, in load_wsgiapp
    return util.import_app(self.app_uri)
  File "/usr/local/lib/python3.5/site-packages/gunicorn/util.py", line 357, in import_app
    __import__(module)
  File "/app/app_wsgi.py", line 16, in <module>
    application = get_wsgi_application()
  File "/usr/local/lib/python3.5/site-packages/django/core/wsgi.py", line 13, in get_wsgi_application
    django.setup()
  File "/usr/local/lib/python3.5/site-packages/django/__init__.py", line 17, in setup
    configure_logging(settings.LOGGING_CONFIG, settings.LOGGING)
  File "/usr/local/lib/python3.5/site-packages/django/conf/__init__.py", line 55, in __getattr__
    self._setup(name)
  File "/usr/local/lib/python3.5/site-packages/django/conf/__init__.py", line 43, in _setup
    self._wrapped = Settings(settings_module)
  File "/usr/local/lib/python3.5/site-packages/django/conf/__init__.py", line 99, in __init__
    mod = importlib.import_module(self.SETTINGS_MODULE)
  File "/usr/local/lib/python3.5/importlib/__init__.py", line 126, in import_module
    return _bootstrap._gcd_import(name[level:], package, level)
ImportError: No module named 'conf'
Traceback (most recent call last):
  File "/usr/local/lib/python3.5/site-packages/gunicorn/arbiter.py", line 515, in spawn_worker
    worker.init_process()
  File "/usr/local/lib/python3.5/site-packages/gunicorn/workers/base.py", line 122, in init_process
    self.load_wsgi()
  File "/usr/local/lib/python3.5/site-packages/gunicorn/workers/base.py", line 130, in load_wsgi
    self.wsgi = self.app.wsgi()
  File "/usr/local/lib/python3.5/site-packages/gunicorn/app/base.py", line 67, in wsgi
    self.callable = self.load()
  File "/usr/local/lib/python3.5/site-packages/gunicorn/app/wsgiapp.py", line 65, in load
    return self.load_wsgiapp()
  File "/usr/local/lib/python3.5/site-packages/gunicorn/app/wsgiapp.py", line 52, in load_wsgiapp
    return util.import_app(self.app_uri)
  File "/usr/local/lib/python3.5/site-packages/gunicorn/util.py", line 357, in import_app
    __import__(module)
  File "/app/app_wsgi.py", line 16, in <module>
    application = get_wsgi_application()
  File "/usr/local/lib/python3.5/site-packages/django/core/wsgi.py", line 13, in get_wsgi_application
    django.setup()
  File "/usr/local/lib/python3.5/site-packages/django/__init__.py", line 17, in setup
    configure_logging(settings.LOGGING_CONFIG, settings.LOGGING)
  File "/usr/local/lib/python3.5/site-packages/django/conf/__init__.py", line 55, in __getattr__
    self._setup(name)
  File "/usr/local/lib/python3.5/site-packages/django/conf/__init__.py", line 43, in _setup
    self._wrapped = Settings(settings_module)
  File "/usr/local/lib/python3.5/site-packages/django/conf/__init__.py", line 99, in __init__
    mod = importlib.import_module(self.SETTINGS_MODULE)
  File "/usr/local/lib/python3.5/importlib/__init__.py", line 126, in import_module
    return _bootstrap._gcd_import(name[level:], package, level)
ImportError: No module named 'conf'
[2016-04-05 18:01:52 +0000] [42] [INFO] Worker exiting (pid: 42)
[2016-04-05 18:01:52 +0000] [46] [ERROR] Exception in worker process:
Traceback (most recent call last):
  File "/usr/local/lib/python3.5/site-packages/gunicorn/arbiter.py", line 515, in spawn_worker
    worker.init_process()
  File "/usr/local/lib/python3.5/site-packages/gunicorn/workers/base.py", line 122, in init_process
    self.load_wsgi()
  File "/usr/local/lib/python3.5/site-packages/gunicorn/workers/base.py", line 130, in load_wsgi
    self.wsgi = self.app.wsgi()
  File "/usr/local/lib/python3.5/site-packages/gunicorn/app/base.py", line 67, in wsgi
    self.callable = self.load()
  File "/usr/local/lib/python3.5/site-packages/gunicorn/app/wsgiapp.py", line 65, in load
    return self.load_wsgiapp()
  File "/usr/local/lib/python3.5/site-packages/gunicorn/app/wsgiapp.py", line 52, in load_wsgiapp
    return util.import_app(self.app_uri)
  File "/usr/local/lib/python3.5/site-packages/gunicorn/util.py", line 357, in import_app
    __import__(module)
  File "/app/app_wsgi.py", line 16, in <module>
    application = get_wsgi_application()
  File "/usr/local/lib/python3.5/site-packages/django/core/wsgi.py", line 13, in get_wsgi_application
    django.setup()
  File "/usr/local/lib/python3.5/site-packages/django/__init__.py", line 17, in setup
    configure_logging(settings.LOGGING_CONFIG, settings.LOGGING)
  File "/usr/local/lib/python3.5/site-packages/django/conf/__init__.py", line 55, in __getattr__
    self._setup(name)
  File "/usr/local/lib/python3.5/site-packages/django/conf/__init__.py", line 43, in _setup
    self._wrapped = Settings(settings_module)
  File "/usr/local/lib/python3.5/site-packages/django/conf/__init__.py", line 99, in __init__
    mod = importlib.import_module(self.SETTINGS_MODULE)
  File "/usr/local/lib/python3.5/importlib/__init__.py", line 126, in import_module
    return _bootstrap._gcd_import(name[level:], package, level)
ImportError: No module named 'conf'
Traceback (most recent call last):
  File "/usr/local/lib/python3.5/site-packages/gunicorn/arbiter.py", line 515, in spawn_worker
    worker.init_process()
  File "/usr/local/lib/python3.5/site-packages/gunicorn/workers/base.py", line 122, in init_process
    self.load_wsgi()
  File "/usr/local/lib/python3.5/site-packages/gunicorn/workers/base.py", line 130, in load_wsgi
    self.wsgi = self.app.wsgi()
  File "/usr/local/lib/python3.5/site-packages/gunicorn/app/base.py", line 67, in wsgi
    self.callable = self.load()
  File "/usr/local/lib/python3.5/site-packages/gunicorn/app/wsgiapp.py", line 65, in load
    return self.load_wsgiapp()
  File "/usr/local/lib/python3.5/site-packages/gunicorn/app/wsgiapp.py", line 52, in load_wsgiapp
    return util.import_app(self.app_uri)
  File "/usr/local/lib/python3.5/site-packages/gunicorn/util.py", line 357, in import_app
    __import__(module)
  File "/app/app_wsgi.py", line 16, in <module>
    application = get_wsgi_application()
  File "/usr/local/lib/python3.5/site-packages/django/core/wsgi.py", line 13, in get_wsgi_application
    django.setup()
  File "/usr/local/lib/python3.5/site-packages/django/__init__.py", line 17, in setup
    configure_logging(settings.LOGGING_CONFIG, settings.LOGGING)
  File "/usr/local/lib/python3.5/site-packages/django/conf/__init__.py", line 55, in __getattr__
    self._setup(name)
  File "/usr/local/lib/python3.5/site-packages/django/conf/__init__.py", line 43, in _setup
    self._wrapped = Settings(settings_module)
  File "/usr/local/lib/python3.5/site-packages/django/conf/__init__.py", line 99, in __init__
    mod = importlib.import_module(self.SETTINGS_MODULE)
  File "/usr/local/lib/python3.5/importlib/__init__.py", line 126, in import_module
    return _bootstrap._gcd_import(name[level:], package, level)
ImportError: No module named 'conf'
[2016-04-05 18:01:52 +0000] [46] [INFO] Worker exiting (pid: 46)
[2016-04-05 18:01:56 +0000] [48] [INFO] Starting gunicorn 19.4.5
[2016-04-05 18:01:56 +0000] [48] [INFO] Listening at: http://0.0.0.0:8000 (48)
[2016-04-05 18:01:56 +0000] [48] [INFO] Using worker: sync
[2016-04-05 18:01:56 +0000] [51] [INFO] Booting worker with pid: 51
[2016-04-05 18:01:56 +0000] [51] [ERROR] Exception in worker process:
Traceback (most recent call last):
  File "/usr/local/lib/python3.5/site-packages/gunicorn/arbiter.py", line 515, in spawn_worker
    worker.init_process()
  File "/usr/local/lib/python3.5/site-packages/gunicorn/workers/base.py", line 122, in init_process
    self.load_wsgi()
  File "/usr/local/lib/python3.5/site-packages/gunicorn/workers/base.py", line 130, in load_wsgi
    self.wsgi = self.app.wsgi()
  File "/usr/local/lib/python3.5/site-packages/gunicorn/app/base.py", line 67, in wsgi
    self.callable = self.load()
  File "/usr/local/lib/python3.5/site-packages/gunicorn/app/wsgiapp.py", line 65, in load
    return self.load_wsgiapp()
  File "/usr/local/lib/python3.5/site-packages/gunicorn/app/wsgiapp.py", line 52, in load_wsgiapp
    return util.import_app(self.app_uri)
  File "/usr/local/lib/python3.5/site-packages/gunicorn/util.py", line 357, in import_app
    __import__(module)
ImportError: No module named 'app_wsg'
Traceback (most recent call last):
  File "/usr/local/lib/python3.5/site-packages/gunicorn/arbiter.py", line 515, in spawn_worker
    worker.init_process()
  File "/usr/local/lib/python3.5/site-packages/gunicorn/workers/base.py", line 122, in init_process
    self.load_wsgi()
  File "/usr/local/lib/python3.5/site-packages/gunicorn/workers/base.py", line 130, in load_wsgi
    self.wsgi = self.app.wsgi()
  File "/usr/local/lib/python3.5/site-packages/gunicorn/app/base.py", line 67, in wsgi
    self.callable = self.load()
  File "/usr/local/lib/python3.5/site-packages/gunicorn/app/wsgiapp.py", line 65, in load
    return self.load_wsgiapp()
  File "/usr/local/lib/python3.5/site-packages/gunicorn/app/wsgiapp.py", line 52, in load_wsgiapp
    return util.import_app(self.app_uri)
  File "/usr/local/lib/python3.5/site-packages/gunicorn/util.py", line 357, in import_app
    __import__(module)
ImportError: No module named 'app_wsg'
[2016-04-05 18:01:56 +0000] [51] [INFO] Worker exiting (pid: 51)
[2016-04-05 18:01:56 +0000] [48] [INFO] Shutting down: Master
[2016-04-05 18:01:56 +0000] [48] [INFO] Reason: Worker failed to boot.
[2016-04-05 18:02:00 +0000] [52] [INFO] Starting gunicorn 19.4.5
[2016-04-05 18:02:00 +0000] [52] [INFO] Listening at: http://0.0.0.0:8000 (52)
[2016-04-05 18:02:00 +0000] [52] [INFO] Using worker: sync
[2016-04-05 18:02:00 +0000] [55] [INFO] Booting worker with pid: 55
[2016-04-05 18:02:00 +0000] [56] [INFO] Booting worker with pid: 56
[2016-04-05 18:02:00 +0000] [58] [INFO] Booting worker with pid: 58
[2016-04-05 18:02:00 +0000] [55] [ERROR] Exception in worker process:
Traceback (most recent call last):
  File "/usr/local/lib/python3.5/site-packages/gunicorn/arbiter.py", line 515, in spawn_worker
    worker.init_process()
  File "/usr/local/lib/python3.5/site-packages/gunicorn/workers/base.py", line 122, in init_process
    self.load_wsgi()
  File "/usr/local/lib/python3.5/site-packages/gunicorn/workers/base.py", line 130, in load_wsgi
    self.wsgi = self.app.wsgi()
  File "/usr/local/lib/python3.5/site-packages/gunicorn/app/base.py", line 67, in wsgi
    self.callable = self.load()
  File "/usr/local/lib/python3.5/site-packages/gunicorn/app/wsgiapp.py", line 65, in load
    return self.load_wsgiapp()
  File "/usr/local/lib/python3.5/site-packages/gunicorn/app/wsgiapp.py", line 52, in load_wsgiapp
    return util.import_app(self.app_uri)
  File "/usr/local/lib/python3.5/site-packages/gunicorn/util.py", line 357, in import_app
    __import__(module)
  File "/app/app_wsgi.py", line 16, in <module>
    application = get_wsgi_application()
  File "/usr/local/lib/python3.5/site-packages/django/core/wsgi.py", line 13, in get_wsgi_application
    django.setup()
  File "/usr/local/lib/python3.5/site-packages/django/__init__.py", line 17, in setup
    configure_logging(settings.LOGGING_CONFIG, settings.LOGGING)
  File "/usr/local/lib/python3.5/site-packages/django/conf/__init__.py", line 55, in __getattr__
    self._setup(name)
  File "/usr/local/lib/python3.5/site-packages/django/conf/__init__.py", line 43, in _setup
    self._wrapped = Settings(settings_module)
  File "/usr/local/lib/python3.5/site-packages/django/conf/__init__.py", line 99, in __init__
    mod = importlib.import_module(self.SETTINGS_MODULE)
  File "/usr/local/lib/python3.5/importlib/__init__.py", line 126, in import_module
    return _bootstrap._gcd_import(name[level:], package, level)
ImportError: No module named 'conf'
Traceback (most recent call last):
  File "/usr/local/lib/python3.5/site-packages/gunicorn/arbiter.py", line 515, in spawn_worker
    worker.init_process()
  File "/usr/local/lib/python3.5/site-packages/gunicorn/workers/base.py", line 122, in init_process
    self.load_wsgi()
  File "/usr/local/lib/python3.5/site-packages/gunicorn/workers/base.py", line 130, in load_wsgi
    self.wsgi = self.app.wsgi()
  File "/usr/local/lib/python3.5/site-packages/gunicorn/app/base.py", line 67, in wsgi
    self.callable = self.load()
  File "/usr/local/lib/python3.5/site-packages/gunicorn/app/wsgiapp.py", line 65, in load
    return self.load_wsgiapp()
  File "/usr/local/lib/python3.5/site-packages/gunicorn/app/wsgiapp.py", line 52, in load_wsgiapp
    return util.import_app(self.app_uri)
  File "/usr/local/lib/python3.5/site-packages/gunicorn/util.py", line 357, in import_app
    __import__(module)
  File "/app/app_wsgi.py", line 16, in <module>
    application = get_wsgi_application()
  File "/usr/local/lib/python3.5/site-packages/django/core/wsgi.py", line 13, in get_wsgi_application
    django.setup()
  File "/usr/local/lib/python3.5/site-packages/django/__init__.py", line 17, in setup
    configure_logging(settings.LOGGING_CONFIG, settings.LOGGING)
  File "/usr/local/lib/python3.5/site-packages/django/conf/__init__.py", line 55, in __getattr__
    self._setup(name)
  File "/usr/local/lib/python3.5/site-packages/django/conf/__init__.py", line 43, in _setup
    self._wrapped = Settings(settings_module)
  File "/usr/local/lib/python3.5/site-packages/django/conf/__init__.py", line 99, in __init__
    mod = importlib.import_module(self.SETTINGS_MODULE)
  File "/usr/local/lib/python3.5/importlib/__init__.py", line 126, in import_module
    return _bootstrap._gcd_import(name[level:], package, level)
ImportError: No module named 'conf'
[2016-04-05 18:02:00 +0000] [55] [INFO] Worker exiting (pid: 55)
[2016-04-05 18:02:00 +0000] [60] [INFO] Booting worker with pid: 60
[2016-04-05 18:02:00 +0000] [62] [INFO] Booting worker with pid: 62
[2016-04-05 18:02:00 +0000] [56] [ERROR] Exception in worker process:
Traceback (most recent call last):
  File "/usr/local/lib/python3.5/site-packages/gunicorn/arbiter.py", line 515, in spawn_worker
    worker.init_process()
  File "/usr/local/lib/python3.5/site-packages/gunicorn/workers/base.py", line 122, in init_process
    self.load_wsgi()
  File "/usr/local/lib/python3.5/site-packages/gunicorn/workers/base.py", line 130, in load_wsgi
    self.wsgi = self.app.wsgi()
  File "/usr/local/lib/python3.5/site-packages/gunicorn/app/base.py", line 67, in wsgi
    self.callable = self.load()
  File "/usr/local/lib/python3.5/site-packages/gunicorn/app/wsgiapp.py", line 65, in load
    return self.load_wsgiapp()
  File "/usr/local/lib/python3.5/site-packages/gunicorn/app/wsgiapp.py", line 52, in load_wsgiapp
    return util.import_app(self.app_uri)
  File "/usr/local/lib/python3.5/site-packages/gunicorn/util.py", line 357, in import_app
    __import__(module)
  File "/app/app_wsgi.py", line 16, in <module>
    application = get_wsgi_application()
  File "/usr/local/lib/python3.5/site-packages/django/core/wsgi.py", line 13, in get_wsgi_application
    django.setup()
  File "/usr/local/lib/python3.5/site-packages/django/__init__.py", line 17, in setup
    configure_logging(settings.LOGGING_CONFIG, settings.LOGGING)
  File "/usr/local/lib/python3.5/site-packages/django/conf/__init__.py", line 55, in __getattr__
    self._setup(name)
  File "/usr/local/lib/python3.5/site-packages/django/conf/__init__.py", line 43, in _setup
    self._wrapped = Settings(settings_module)
  File "/usr/local/lib/python3.5/site-packages/django/conf/__init__.py", line 99, in __init__
    mod = importlib.import_module(self.SETTINGS_MODULE)
  File "/usr/local/lib/python3.5/importlib/__init__.py", line 126, in import_module
    return _bootstrap._gcd_import(name[level:], package, level)
ImportError: No module named 'conf'
Traceback (most recent call last):
  File "/usr/local/lib/python3.5/site-packages/gunicorn/arbiter.py", line 515, in spawn_worker
    worker.init_process()
  File "/usr/local/lib/python3.5/site-packages/gunicorn/workers/base.py", line 122, in init_process
    self.load_wsgi()
  File "/usr/local/lib/python3.5/site-packages/gunicorn/workers/base.py", line 130, in load_wsgi
    self.wsgi = self.app.wsgi()
  File "/usr/local/lib/python3.5/site-packages/gunicorn/app/base.py", line 67, in wsgi
    self.callable = self.load()
  File "/usr/local/lib/python3.5/site-packages/gunicorn/app/wsgiapp.py", line 65, in load
    return self.load_wsgiapp()
  File "/usr/local/lib/python3.5/site-packages/gunicorn/app/wsgiapp.py", line 52, in load_wsgiapp
    return util.import_app(self.app_uri)
  File "/usr/local/lib/python3.5/site-packages/gunicorn/util.py", line 357, in import_app
    __import__(module)
  File "/app/app_wsgi.py", line 16, in <module>
    application = get_wsgi_application()
  File "/usr/local/lib/python3.5/site-packages/django/core/wsgi.py", line 13, in get_wsgi_application
    django.setup()
  File "/usr/local/lib/python3.5/site-packages/django/__init__.py", line 17, in setup
    configure_logging(settings.LOGGING_CONFIG, settings.LOGGING)
  File "/usr/local/lib/python3.5/site-packages/django/conf/__init__.py", line 55, in __getattr__
    self._setup(name)
  File "/usr/local/lib/python3.5/site-packages/django/conf/__init__.py", line 43, in _setup
    self._wrapped = Settings(settings_module)
  File "/usr/local/lib/python3.5/site-packages/django/conf/__init__.py", line 99, in __init__
    mod = importlib.import_module(self.SETTINGS_MODULE)
  File "/usr/local/lib/python3.5/importlib/__init__.py", line 126, in import_module
    return _bootstrap._gcd_import(name[level:], package, level)
ImportError: No module named 'conf'
[2016-04-05 18:02:00 +0000] [56] [INFO] Worker exiting (pid: 56)
[2016-04-05 18:02:00 +0000] [58] [ERROR] Exception in worker process:
Traceback (most recent call last):
  File "/usr/local/lib/python3.5/site-packages/gunicorn/arbiter.py", line 515, in spawn_worker
    worker.init_process()
  File "/usr/local/lib/python3.5/site-packages/gunicorn/workers/base.py", line 122, in init_process
    self.load_wsgi()
  File "/usr/local/lib/python3.5/site-packages/gunicorn/workers/base.py", line 130, in load_wsgi
    self.wsgi = self.app.wsgi()
  File "/usr/local/lib/python3.5/site-packages/gunicorn/app/base.py", line 67, in wsgi
    self.callable = self.load()
  File "/usr/local/lib/python3.5/site-packages/gunicorn/app/wsgiapp.py", line 65, in load
    return self.load_wsgiapp()
  File "/usr/local/lib/python3.5/site-packages/gunicorn/app/wsgiapp.py", line 52, in load_wsgiapp
    return util.import_app(self.app_uri)
  File "/usr/local/lib/python3.5/site-packages/gunicorn/util.py", line 357, in import_app
    __import__(module)
  File "/app/app_wsgi.py", line 16, in <module>
    application = get_wsgi_application()
  File "/usr/local/lib/python3.5/site-packages/django/core/wsgi.py", line 13, in get_wsgi_application
    django.setup()
  File "/usr/local/lib/python3.5/site-packages/django/__init__.py", line 17, in setup
    configure_logging(settings.LOGGING_CONFIG, settings.LOGGING)
  File "/usr/local/lib/python3.5/site-packages/django/conf/__init__.py", line 55, in __getattr__
    self._setup(name)
  File "/usr/local/lib/python3.5/site-packages/django/conf/__init__.py", line 43, in _setup
    self._wrapped = Settings(settings_module)
  File "/usr/local/lib/python3.5/site-packages/django/conf/__init__.py", line 99, in __init__
    mod = importlib.import_module(self.SETTINGS_MODULE)
  File "/usr/local/lib/python3.5/importlib/__init__.py", line 126, in import_module
    return _bootstrap._gcd_import(name[level:], package, level)
ImportError: No module named 'conf'
Traceback (most recent call last):
  File "/usr/local/lib/python3.5/site-packages/gunicorn/arbiter.py", line 515, in spawn_worker
    worker.init_process()
  File "/usr/local/lib/python3.5/site-packages/gunicorn/workers/base.py", line 122, in init_process
    self.load_wsgi()
  File "/usr/local/lib/python3.5/site-packages/gunicorn/workers/base.py", line 130, in load_wsgi
    self.wsgi = self.app.wsgi()
  File "/usr/local/lib/python3.5/site-packages/gunicorn/app/base.py", line 67, in wsgi
    self.callable = self.load()
  File "/usr/local/lib/python3.5/site-packages/gunicorn/app/wsgiapp.py", line 65, in load
    return self.load_wsgiapp()
  File "/usr/local/lib/python3.5/site-packages/gunicorn/app/wsgiapp.py", line 52, in load_wsgiapp
    return util.import_app(self.app_uri)
  File "/usr/local/lib/python3.5/site-packages/gunicorn/util.py", line 357, in import_app
    __import__(module)
  File "/app/app_wsgi.py", line 16, in <module>
    application = get_wsgi_application()
  File "/usr/local/lib/python3.5/site-packages/django/core/wsgi.py", line 13, in get_wsgi_application
    django.setup()
  File "/usr/local/lib/python3.5/site-packages/django/__init__.py", line 17, in setup
    configure_logging(settings.LOGGING_CONFIG, settings.LOGGING)
  File "/usr/local/lib/python3.5/site-packages/django/conf/__init__.py", line 55, in __getattr__
    self._setup(name)
  File "/usr/local/lib/python3.5/site-packages/django/conf/__init__.py", line 43, in _setup
    self._wrapped = Settings(settings_module)
  File "/usr/local/lib/python3.5/site-packages/django/conf/__init__.py", line 99, in __init__
    mod = importlib.import_module(self.SETTINGS_MODULE)
  File "/usr/local/lib/python3.5/importlib/__init__.py", line 126, in import_module
    return _bootstrap._gcd_import(name[level:], package, level)
ImportError: No module named 'conf'
[2016-04-05 18:02:00 +0000] [58] [INFO] Worker exiting (pid: 58)
[2016-04-05 18:02:00 +0000] [60] [ERROR] Exception in worker process:
Traceback (most recent call last):
  File "/usr/local/lib/python3.5/site-packages/gunicorn/arbiter.py", line 515, in spawn_worker
    worker.init_process()
  File "/usr/local/lib/python3.5/site-packages/gunicorn/workers/base.py", line 122, in init_process
    self.load_wsgi()
  File "/usr/local/lib/python3.5/site-packages/gunicorn/workers/base.py", line 130, in load_wsgi
    self.wsgi = self.app.wsgi()
  File "/usr/local/lib/python3.5/site-packages/gunicorn/app/base.py", line 67, in wsgi
    self.callable = self.load()
  File "/usr/local/lib/python3.5/site-packages/gunicorn/app/wsgiapp.py", line 65, in load
    return self.load_wsgiapp()
  File "/usr/local/lib/python3.5/site-packages/gunicorn/app/wsgiapp.py", line 52, in load_wsgiapp
    return util.import_app(self.app_uri)
  File "/usr/local/lib/python3.5/site-packages/gunicorn/util.py", line 357, in import_app
    __import__(module)
  File "/app/app_wsgi.py", line 16, in <module>
    application = get_wsgi_application()
  File "/usr/local/lib/python3.5/site-packages/django/core/wsgi.py", line 13, in get_wsgi_application
    django.setup()
  File "/usr/local/lib/python3.5/site-packages/django/__init__.py", line 17, in setup
    configure_logging(settings.LOGGING_CONFIG, settings.LOGGING)
  File "/usr/local/lib/python3.5/site-packages/django/conf/__init__.py", line 55, in __getattr__
    self._setup(name)
  File "/usr/local/lib/python3.5/site-packages/django/conf/__init__.py", line 43, in _setup
    self._wrapped = Settings(settings_module)
  File "/usr/local/lib/python3.5/site-packages/django/conf/__init__.py", line 99, in __init__
    mod = importlib.import_module(self.SETTINGS_MODULE)
  File "/usr/local/lib/python3.5/importlib/__init__.py", line 126, in import_module
    return _bootstrap._gcd_import(name[level:], package, level)
ImportError: No module named 'conf'
Traceback (most recent call last):
  File "/usr/local/lib/python3.5/site-packages/gunicorn/arbiter.py", line 515, in spawn_worker
    worker.init_process()
  File "/usr/local/lib/python3.5/site-packages/gunicorn/workers/base.py", line 122, in init_process
    self.load_wsgi()
  File "/usr/local/lib/python3.5/site-packages/gunicorn/workers/base.py", line 130, in load_wsgi
    self.wsgi = self.app.wsgi()
  File "/usr/local/lib/python3.5/site-packages/gunicorn/app/base.py", line 67, in wsgi
    self.callable = self.load()
  File "/usr/local/lib/python3.5/site-packages/gunicorn/app/wsgiapp.py", line 65, in load
    return self.load_wsgiapp()
  File "/usr/local/lib/python3.5/site-packages/gunicorn/app/wsgiapp.py", line 52, in load_wsgiapp
    return util.import_app(self.app_uri)
  File "/usr/local/lib/python3.5/site-packages/gunicorn/util.py", line 357, in import_app
    __import__(module)
  File "/app/app_wsgi.py", line 16, in <module>
    application = get_wsgi_application()
  File "/usr/local/lib/python3.5/site-packages/django/core/wsgi.py", line 13, in get_wsgi_application
    django.setup()
  File "/usr/local/lib/python3.5/site-packages/django/__init__.py", line 17, in setup
    configure_logging(settings.LOGGING_CONFIG, settings.LOGGING)
  File "/usr/local/lib/python3.5/site-packages/django/conf/__init__.py", line 55, in __getattr__
    self._setup(name)
  File "/usr/local/lib/python3.5/site-packages/django/conf/__init__.py", line 43, in _setup
    self._wrapped = Settings(settings_module)
  File "/usr/local/lib/python3.5/site-packages/django/conf/__init__.py", line 99, in __init__
    mod = importlib.import_module(self.SETTINGS_MODULE)
  File "/usr/local/lib/python3.5/importlib/__init__.py", line 126, in import_module
    return _bootstrap._gcd_import(name[level:], package, level)
ImportError: No module named 'conf'
[2016-04-05 18:02:00 +0000] [60] [INFO] Worker exiting (pid: 60)
[2016-04-05 18:02:00 +0000] [62] [ERROR] Exception in worker process:
Traceback (most recent call last):
  File "/usr/local/lib/python3.5/site-packages/gunicorn/arbiter.py", line 515, in spawn_worker
    worker.init_process()
  File "/usr/local/lib/python3.5/site-packages/gunicorn/workers/base.py", line 122, in init_process
    self.load_wsgi()
  File "/usr/local/lib/python3.5/site-packages/gunicorn/workers/base.py", line 130, in load_wsgi
    self.wsgi = self.app.wsgi()
  File "/usr/local/lib/python3.5/site-packages/gunicorn/app/base.py", line 67, in wsgi
    self.callable = self.load()
  File "/usr/local/lib/python3.5/site-packages/gunicorn/app/wsgiapp.py", line 65, in load
    return self.load_wsgiapp()
  File "/usr/local/lib/python3.5/site-packages/gunicorn/app/wsgiapp.py", line 52, in load_wsgiapp
    return util.import_app(self.app_uri)
  File "/usr/local/lib/python3.5/site-packages/gunicorn/util.py", line 357, in import_app
    __import__(module)
  File "/app/app_wsgi.py", line 16, in <module>
    application = get_wsgi_application()
  File "/usr/local/lib/python3.5/site-packages/django/core/wsgi.py", line 13, in get_wsgi_application
    django.setup()
  File "/usr/local/lib/python3.5/site-packages/django/__init__.py", line 17, in setup
    configure_logging(settings.LOGGING_CONFIG, settings.LOGGING)
  File "/usr/local/lib/python3.5/site-packages/django/conf/__init__.py", line 55, in __getattr__
    self._setup(name)
  File "/usr/local/lib/python3.5/site-packages/django/conf/__init__.py", line 43, in _setup
    self._wrapped = Settings(settings_module)
  File "/usr/local/lib/python3.5/site-packages/django/conf/__init__.py", line 99, in __init__
    mod = importlib.import_module(self.SETTINGS_MODULE)
  File "/usr/local/lib/python3.5/importlib/__init__.py", line 126, in import_module
    return _bootstrap._gcd_import(name[level:], package, level)
ImportError: No module named 'conf'
Traceback (most recent call last):
  File "/usr/local/lib/python3.5/site-packages/gunicorn/arbiter.py", line 515, in spawn_worker
    worker.init_process()
  File "/usr/local/lib/python3.5/site-packages/gunicorn/workers/base.py", line 122, in init_process
    self.load_wsgi()
  File "/usr/local/lib/python3.5/site-packages/gunicorn/workers/base.py", line 130, in load_wsgi
    self.wsgi = self.app.wsgi()
  File "/usr/local/lib/python3.5/site-packages/gunicorn/app/base.py", line 67, in wsgi
    self.callable = self.load()
  File "/usr/local/lib/python3.5/site-packages/gunicorn/app/wsgiapp.py", line 65, in load
    return self.load_wsgiapp()
  File "/usr/local/lib/python3.5/site-packages/gunicorn/app/wsgiapp.py", line 52, in load_wsgiapp
    return util.import_app(self.app_uri)
  File "/usr/local/lib/python3.5/site-packages/gunicorn/util.py", line 357, in import_app
    __import__(module)
  File "/app/app_wsgi.py", line 16, in <module>
    application = get_wsgi_application()
  File "/usr/local/lib/python3.5/site-packages/django/core/wsgi.py", line 13, in get_wsgi_application
    django.setup()
  File "/usr/local/lib/python3.5/site-packages/django/__init__.py", line 17, in setup
    configure_logging(settings.LOGGING_CONFIG, settings.LOGGING)
  File "/usr/local/lib/python3.5/site-packages/django/conf/__init__.py", line 55, in __getattr__
    self._setup(name)
  File "/usr/local/lib/python3.5/site-packages/django/conf/__init__.py", line 43, in _setup
    self._wrapped = Settings(settings_module)
  File "/usr/local/lib/python3.5/site-packages/django/conf/__init__.py", line 99, in __init__
    mod = importlib.import_module(self.SETTINGS_MODULE)
  File "/usr/local/lib/python3.5/importlib/__init__.py", line 126, in import_module
    return _bootstrap._gcd_import(name[level:], package, level)
ImportError: No module named 'conf'
[2016-04-05 18:02:00 +0000] [62] [INFO] Worker exiting (pid: 62)
[2016-04-05 18:11:01 +0000] [9] [INFO] Starting gunicorn 19.4.5
[2016-04-05 18:11:01 +0000] [9] [INFO] Listening at: http://0.0.0.0:8000 (9)
[2016-04-05 18:11:01 +0000] [9] [INFO] Using worker: sync
[2016-04-05 18:11:01 +0000] [12] [INFO] Booting worker with pid: 12
[2016-04-05 18:11:01 +0000] [14] [INFO] Booting worker with pid: 14
[2016-04-05 18:11:01 +0000] [15] [INFO] Booting worker with pid: 15
[2016-04-05 18:11:01 +0000] [17] [INFO] Booting worker with pid: 17
[2016-04-05 18:11:02 +0000] [19] [INFO] Booting worker with pid: 19
[2016-04-05 18:11:02 +0000] [21] [INFO] Booting worker with pid: 21
[2016-04-05 18:11:02 +0000] [23] [INFO] Booting worker with pid: 23
[2016-04-05 18:11:02 +0000] [22] [INFO] Booting worker with pid: 22
[2016-04-05 18:11:02 +0000] [24] [INFO] Booting worker with pid: 24
[2016-04-05 18:11:28 +0000] [8] [INFO] Starting gunicorn 19.4.5
[2016-04-05 18:11:28 +0000] [8] [INFO] Listening at: http://0.0.0.0:8000 (8)
[2016-04-05 18:11:28 +0000] [8] [INFO] Using worker: sync
[2016-04-05 18:11:28 +0000] [11] [INFO] Booting worker with pid: 11
[2016-04-05 18:11:28 +0000] [13] [INFO] Booting worker with pid: 13
[2016-04-05 18:11:28 +0000] [14] [INFO] Booting worker with pid: 14
[2016-04-05 18:11:28 +0000] [16] [INFO] Booting worker with pid: 16
[2016-04-05 18:11:28 +0000] [18] [INFO] Booting worker with pid: 18
[2016-04-05 18:11:28 +0000] [19] [INFO] Booting worker with pid: 19
[2016-04-05 18:11:28 +0000] [21] [INFO] Booting worker with pid: 21
[2016-04-05 18:11:28 +0000] [24] [INFO] Booting worker with pid: 24
[2016-04-05 18:11:28 +0000] [26] [INFO] Booting worker with pid: 26
[2016-04-06 17:47:07 +0000] [9] [INFO] Starting gunicorn 19.4.5
[2016-04-06 17:47:07 +0000] [9] [INFO] Listening at: http://0.0.0.0:8000 (9)
[2016-04-06 17:47:07 +0000] [9] [INFO] Using worker: sync
[2016-04-06 17:47:07 +0000] [12] [INFO] Booting worker with pid: 12
[2016-04-06 17:47:07 +0000] [13] [INFO] Booting worker with pid: 13
[2016-04-06 17:47:07 +0000] [16] [INFO] Booting worker with pid: 16
[2016-04-06 17:47:07 +0000] [17] [INFO] Booting worker with pid: 17
[2016-04-06 17:47:07 +0000] [20] [INFO] Booting worker with pid: 20
[2016-04-06 17:47:07 +0000] [21] [INFO] Booting worker with pid: 21
[2016-04-06 17:47:08 +0000] [23] [INFO] Booting worker with pid: 23
[2016-04-06 17:47:08 +0000] [25] [INFO] Booting worker with pid: 25
[2016-04-06 17:47:08 +0000] [27] [INFO] Booting worker with pid: 27
[2016-04-06 17:47:30 +0000] [9] [INFO] Starting gunicorn 19.4.5
[2016-04-06 17:47:30 +0000] [9] [INFO] Listening at: http://0.0.0.0:8000 (9)
[2016-04-06 17:47:30 +0000] [9] [INFO] Using worker: sync
[2016-04-06 17:47:30 +0000] [12] [INFO] Booting worker with pid: 12
[2016-04-06 17:47:30 +0000] [14] [INFO] Booting worker with pid: 14
[2016-04-06 17:47:30 +0000] [16] [INFO] Booting worker with pid: 16
[2016-04-06 17:47:30 +0000] [17] [INFO] Booting worker with pid: 17
[2016-04-06 17:47:30 +0000] [18] [INFO] Booting worker with pid: 18
[2016-04-06 17:47:30 +0000] [19] [INFO] Booting worker with pid: 19
[2016-04-06 17:47:30 +0000] [20] [INFO] Booting worker with pid: 20
[2016-04-06 17:47:30 +0000] [24] [INFO] Booting worker with pid: 24
[2016-04-06 17:47:30 +0000] [26] [INFO] Booting worker with pid: 26
[2016-04-06 18:01:15 +0000] [8] [INFO] Starting gunicorn 19.4.5
[2016-04-06 18:01:15 +0000] [8] [INFO] Listening at: http://0.0.0.0:8000 (8)
[2016-04-06 18:01:15 +0000] [8] [INFO] Using worker: sync
[2016-04-06 18:01:15 +0000] [11] [INFO] Booting worker with pid: 11
[2016-04-06 18:01:15 +0000] [12] [INFO] Booting worker with pid: 12
[2016-04-06 18:01:15 +0000] [13] [INFO] Booting worker with pid: 13
[2016-04-06 18:01:15 +0000] [17] [INFO] Booting worker with pid: 17
[2016-04-06 18:01:15 +0000] [18] [INFO] Booting worker with pid: 18
[2016-04-06 18:01:15 +0000] [21] [INFO] Booting worker with pid: 21
[2016-04-06 18:01:15 +0000] [23] [INFO] Booting worker with pid: 23
[2016-04-06 18:01:15 +0000] [22] [INFO] Booting worker with pid: 22
[2016-04-06 18:01:15 +0000] [24] [INFO] Booting worker with pid: 24
[2016-04-06 18:14:57 +0000] [12] [INFO] Starting gunicorn 19.4.5
[2016-04-06 18:14:57 +0000] [12] [INFO] Listening at: http://0.0.0.0:8000 (12)
[2016-04-06 18:14:57 +0000] [12] [INFO] Using worker: sync
[2016-04-06 18:14:57 +0000] [15] [INFO] Booting worker with pid: 15
[2016-04-06 18:14:57 +0000] [17] [INFO] Booting worker with pid: 17
[2016-04-06 18:14:57 +0000] [19] [INFO] Booting worker with pid: 19
[2016-04-06 18:14:57 +0000] [20] [INFO] Booting worker with pid: 20
[2016-04-06 18:14:57 +0000] [22] [INFO] Booting worker with pid: 22
[2016-04-06 18:14:57 +0000] [24] [INFO] Booting worker with pid: 24
[2016-04-06 18:14:57 +0000] [26] [INFO] Booting worker with pid: 26
[2016-04-06 18:14:57 +0000] [27] [INFO] Booting worker with pid: 27
[2016-04-06 18:14:57 +0000] [29] [INFO] Booting worker with pid: 29
[2016-04-06 18:21:19 +0000] [11] [INFO] Starting gunicorn 19.4.5
[2016-04-06 18:21:19 +0000] [11] [INFO] Listening at: http://0.0.0.0:8000 (11)
[2016-04-06 18:21:19 +0000] [11] [INFO] Using worker: sync
[2016-04-06 18:21:19 +0000] [14] [INFO] Booting worker with pid: 14
[2016-04-06 18:21:19 +0000] [16] [INFO] Booting worker with pid: 16
[2016-04-06 18:21:19 +0000] [18] [INFO] Booting worker with pid: 18
[2016-04-06 18:21:20 +0000] [19] [INFO] Booting worker with pid: 19
[2016-04-06 18:21:20 +0000] [20] [INFO] Booting worker with pid: 20
[2016-04-06 18:21:20 +0000] [23] [INFO] Booting worker with pid: 23
[2016-04-06 18:21:20 +0000] [25] [INFO] Booting worker with pid: 25
[2016-04-06 18:21:20 +0000] [27] [INFO] Booting worker with pid: 27
[2016-04-06 18:21:20 +0000] [28] [INFO] Booting worker with pid: 28
[2016-04-06 18:23:47 +0000] [12] [INFO] Starting gunicorn 19.4.5
[2016-04-06 18:23:47 +0000] [12] [INFO] Listening at: http://0.0.0.0:8000 (12)
[2016-04-06 18:23:47 +0000] [12] [INFO] Using worker: sync
[2016-04-06 18:23:47 +0000] [15] [INFO] Booting worker with pid: 15
[2016-04-06 18:23:47 +0000] [16] [INFO] Booting worker with pid: 16
[2016-04-06 18:23:47 +0000] [19] [INFO] Booting worker with pid: 19
[2016-04-06 18:23:47 +0000] [20] [INFO] Booting worker with pid: 20
[2016-04-06 18:23:47 +0000] [23] [INFO] Booting worker with pid: 23
[2016-04-06 18:23:47 +0000] [24] [INFO] Booting worker with pid: 24
[2016-04-06 18:23:47 +0000] [25] [INFO] Booting worker with pid: 25
[2016-04-06 18:23:47 +0000] [27] [INFO] Booting worker with pid: 27
[2016-04-06 18:23:47 +0000] [29] [INFO] Booting worker with pid: 29
